Workbook

Sheet Sheet1
A5: Tính năng | B5: DE - Dữ liệu giao dịch - Công ty
A6: Ngày trích xuất | B6: 46157.723 | F6: room còn lại | G6: =G11/G7 | K6: room còn lại | L6: =L11/L7 | P6: room còn lại | Q6: =Q11/Q7 | U6: room còn lại | V6: =V11/V7
F7: slcplh | G7: 5136656599 | K7: slcplh | L7: 3404005710 | P7: slcplh | Q7: 7933923601 | U7: slcplh | V7: 7086240414
C8: ACB | H8: VIB | M8: VPB | R8: TCB
A9: STT | B9: Ngày | C9: Khối lượng NĐTNN mua (D) Đơn vị: Cổ phiếu | D9: Khối lượng NĐTNN bán (D) Đơn vị: Cổ phiếu | E9: KL ròng | F9: Luỹ kế | G9: Khối lượng khối ngoại còn được phép mua (D) Đơn vị: Cổ phiếu | H9: Khối lượng NĐTNN mua (D) Đơn vị: Cổ phiếu | I9: Khối lượng NĐTNN bán (D) Đơn vị: Cổ phiếu | J9: KL ròng | K9: Luỹ kế | L9: Khối lượng khối ngoại còn được phép mua (D) Đơn vị: Cổ phiếu | M9: Khối lượng NĐTNN mua (D) Đơn vị: Cổ phiếu | N9: Khối lượng NĐTNN bán (D) Đơn vị: Cổ phiếu | O9: KL ròng | P9: Luỹ kế | Q9: Khối lượng khối ngoại còn được phép mua (D) Đơn vị: Cổ phiếu | R9: Khối lượng NĐTNN mua (D) Đơn vị: Cổ phiếu | S9: Khối lượng NĐTNN bán (D) Đơn vị: Cổ phiếu | T9: KL ròng | U9: Luỹ kế | V9: Khối lượng khối ngoại còn được phép mua (D) Đơn vị: Cổ phiếu
B10: 46276 | C10: 785100 | D10: 1765613 | E10: =C10-D10 | F10: =F11+E10 | H10: 169445 | I10: 381600 | J10: =H10-I10 | K10: =K11+J10 | M10: 2936400 | N10: 7777215 | O10: =M10-N10 | P10: =P11+O10 | R10: 2004479 | S10: 947300 | T10: =R10-S10 | U10: =U11+T10
B11: 46275 | C11: 825309 | D11: 277540 | E11: =C11-D11 | F11: =F12+E11 | G11: 368544592 | H11: 31850 | I11: 118885 | J11: =H11-I11 | K11: =K12+J11 | L11: 53398987 | M11: 1931300 | N11: 893104 | O11: =M11-N11 | P11: =P12+O11 | Q11: 570178728 | R11: 1407500 | S11: 457600 | T11: =R11-S11 | U11: =U12+T11 | V11: 122283076
B12: 46274 | C12: 1868900 | D12: 2577000 | E12: =C12-D12 | F12: =F13+E12 | G12: 369092361 | H12: 2147500 | I12: 197200 | J12: =H12-I12 | K12: =K13+J12 | L12: 53398987 | M12: 671000 | N12: 2498800 | O12: =M12-N12 | P12: =P13+O12 | Q12: 568383277 | R12: 3829568 | S12: 522300 | T12: =R12-S12 | U12: =U13+T12 | V12: 123079143
B13: 46273 | C13: 516412 | D13: 168700 | E13: =C13-D13 | F13: =F14+E13 | G13: 369065921 | H13: 2855000 | I13: 33068 | J13: =H13-I13 | K13: =K14+J13 | L13: 54887287 | M13: 1765003 | N13: 4598650 | O13: =M13-N13 | P13: =P14+O13 | Q13: 568440277 | R13: 664160 | S13: 817993 | T13: =R13-S13 | U13: =U14+T13 | V13: 125939341
B14: 46272 | C14: 249600 | D14: 341040 | E14: =C14-D14 | F14: =F15+E14 | G14: 367002165 | H14: 133500 | I14: 620500 | J14: =H14-I14 | K14: =K15+J14 | L14: 57709219 | M14: 4124180 | N14: 2885000 | O14: =M14-N14 | P14: =P15+O14 | Q14: 568440277 | R14: 908330 | S14: 1406400 | T14: =R14-S14 | U14: =U15+T14 | V14: 125939341
B15: 46269 | C15: 1723300 | D15: 4134768 | E15: =C15-D15 | F15: =F16+E15 | H15: 2866400 | I15: 890400 | J15: =H15-I15 | K15: =K16+J15 | M15: 5185700 | N15: 1655600 | O15: =M15-N15 | P15: =P16+O15 | R15: 1656600 | S15: 1355600 | T15: =R15-S15 | U15: =U16+T15
B16: 46268 | C16: 1039188 | D16: 4718040 | E16: =C16-D16 | F16: =F17+E16 | G16: 363348113 | H16: 298400 | I16: 416400 | J16: =H16-I16 | K16: =K17+J16 | L16: 59190619 | M16: 1750578 | N16: 8107800 | O16: =M16-N16 | P16: =P17+O16 | Q16: 566873935 | R16: 2189118 | S16: 6949448 | T16: =R16-S16 | U16: =U17+T16 | V16: 121499611
B17: 46262 | C17: 1225600 | D17: 476226 | E17: =C17-D17 | F17: =F18+E17 | H17: 263400 | I17: 649200 | J17: =H17-I17 | K17: =K18+J17 | M17: 5182154 | N17: 1111700 | O17: =M17-N17 | P17: =P18+O17 | R17: 8197392 | S17: 1811500 | T17: =R17-S17 | U17: =U18+T17
B18: 46261 | C18: 1871900 | D18: 1605570 | E18: =C18-D18 | F18: =F19+E18 | G18: 360589986 | H18: 280500 | I18: 1220000 | J18: =H18-I18 | K18: =K19+J18 | L18: 58251119 | M18: 4952400 | N18: 1195600 | O18: =M18-N18 | P18: =P19+O18 | Q18: 570567698 | R18: 14306288 | S18: 1275889 | T18: =R18-S18 | U18: =U19+T18 | V18: 127885503
B19: 46260 | C19: 515100 | D19: 4010001 | E19: =C19-D19 | F19: =F20+E19 | G19: 359225268 | H19: 987900 | I19: 356205 | J19: =H19-I19 | K19: =K20+J19 | L19: 58241919 | M19: 1695210 | N19: 2060801 | O19: =M19-N19 | P19: =P20+O19 | Q19: 574318298 | R19: 7232200 | S19: 3227900 | T19: =R19-S19 | U19: =U20+T19 | V19: 137767142
B20: 46259 | C20: 266960 | D20: 1896408 | E20: =C20-D20 | F20: =F21+E20 | G20: 359225268 | H20: 136600 | I20: 111304 | J20: =H20-I20 | K20: =K21+J20 | L20: 58686814 | M20: 1255300 | N20: 950001 | O20: =M20-N20 | P20: =P21+O20 | Q20: 574314198 | R20: 114040 | S20: 3261400 | T20: =R20-S20 | U20: =U21+T20 | V20: 141771442
B21: 46258 | C21: 501500 | D21: 490839 | E21: =C21-D21 | F21: =F22+E21 | G21: 359233368 | H21: 89800 | I21: 276600 | J21: =H21-I21 | K21: =K22+J21 | L21: 58715110 | M21: 3534232 | N21: 983949 | O21: =M21-N21 | P21: =P22+O21 | Q21: 572499097 | R21: 1095590 | S21: 345362 | T21: =R21-S21 | U21: =U22+T21 | V21: 141771917
B22: 46255 | C22: 1242000 | D22: 636890 | E22: =C22-D22 | F22: =F23+E22 | H22: 647000 | I22: 130100 | J22: =H22-I22 | K22: =K23+J22 | M22: 1538500 | N22: 3665900 | O22: =M22-N22 | P22: =P23+O22 | R22: 411675 | S22: 417600 | T22: =R22-S22 | U22: =U23+T22
B23: 46254 | C23: 391700 | D23: 1719376 | E23: =C23-D23 | F23: =F24+E23 | G23: 356262341 | H23: 56087 | I23: 67000 | J23: =H23-I23 | K23: =K24+J23 | L23: 58972819 | M23: 949051 | N23: 4441900 | O23: =M23-N23 | P23: =P24+O23 | Q23: 567718352 | R23: 547358 | S23: 272004 | T23: =R23-S23 | U23: =U24+T23 | V23: 142522145
B24: 46253 | C24: 484200 | D24: 2919022 | E24: =C24-D24 | F24: =F25+E24 | G24: 355183946 | H24: 84922 | I24: 333200 | J24: =H24-I24 | K24: =K25+J24 | L24: 58529419 | M24: 282251 | N24: 4256230 | O24: =M24-N24 | P24: =P25+O24 | Q24: 562980652 | R24: 907772 | S24: 435400 | T24: =R24-S24 | U24: =U25+T24 | V24: 142797499
B25: 46252 | C25: 410800 | D25: 1489195 | E25: =C25-D25 | F25: =F26+E25 | G25: 349265193 | H25: 60900 | I25: 504300 | J25: =H25-I25 | K25: =K26+J25 | L25: 58186618 | M25: 336800 | N25: 5074500 | O25: =M25-N25 | P25: =P26+O25 | Q25: 560546152 | R25: 838100 | S25: 534200 | T25: =R25-S25 | U25: =U26+T25 | V25: 143573771
B26: 46251 | C26: 362400 | D26: 4731982 | E26: =C26-D26 | F26: =F27+E26 | G26: 349265193 | H26: 243500 | I26: 28100 | J26: =H26-I26 | K26: =K27+J26 | L26: 58186618 | M26: 2108000 | N26: 2925900 | O26: =M26-N26 | P26: =P27+O26 | Q26: 560546152 | R26: 2472985 | S26: 599400 | T26: =R26-S26 | U26: =U27+T26 | V26: 143573771
B27: 46248 | C27: 667500 | D27: 2216671 | E27: =C27-D27 | F27: =F28+E27 | H27: 234700 | I27: 577501 | J27: =H27-I27 | K27: =K28+J27 | M27: 2646300 | N27: 4258800 | O27: =M27-N27 | P27: =P28+O27 | R27: 3833331 | S27: 989700 | T27: =R27-S27 | U27: =U28+T27
B28: 46247 | C28: 1101130 | D28: 5231399 | E28: =C28-D28 | F28: =F29+E28 | G28: 342501437 | H28: 217100 | I28: 46500 | J28: =H28-I28 | K28: =K29+J28 | L28: 58402018 | M28: 2303321 | N28: 3558200 | O28: =M28-N28 | P28: =P29+O28 | Q28: 558812473 | R28: 2060364 | S28: 7414200 | T28: =R28-S28 | U28: =U29+T28 | V28: 141277957
B29: 46246 | C29: 1329616 | D29: 3963103 | E29: =C29-D29 | F29: =F30+E29 | G29: 340131967 | H29: 68300 | I29: 10000 | J29: =H29-I29 | K29: =K30+J29 | L29: 58513318 | M29: 1320800 | N29: 1799600 | O29: =M29-N29 | P29: =P30+O29 | Q29: 557561073 | R29: 1190706 | S29: 2849900 | T29: =R29-S29 | U29: =U30+T29 | V29: 134165457
B30: 46245 | C30: 1291715 | D30: 3796285 | E30: =C30-D30 | F30: =F31+E30 | G30: 339948288 | H30: 35400 | I30: 93100 | J30: =H30-I30 | K30: =K31+J30 | L30: 58571618 | M30: 474600 | N30: 1839300 | O30: =M30-N30 | P30: =P31+O30 | Q30: 556337459 | R30: 410000 | S30: 7537300 | T30: =R30-S30 | U30: =U31+T30 | V30: 122375132
B31: 46244 | C31: 1761900 | D31: 1945579 | E31: =C31-D31 | F31: =F32+E31 | G31: 339942088 | H31: 293800 | I31: 16200 | J31: =H31-I31 | K31: =K32+J31 | L31: 58569318 | M31: 3207386 | N31: 4431000 | O31: =M31-N31 | P31: =P32+O31 | Q31: 548100609 | R31: 1039175 | S31: 12829500 | T31: =R31-S31 | U31: =U32+T31 | V31: 114870832
B32: 46241 | C32: 502750 | D32: 473852 | E32: =C32-D32 | F32: =F33+E32 | H32: 307100 | I32: 110700 | J32: =H32-I32 | K32: =K33+J32 | M32: 916450 | N32: 9143800 | O32: =M32-N32 | P32: =P33+O32 | R32: 1070900 | S32: 8570300 | T32: =R32-S32 | U32: =U33+T32
B33: 46240 | C33: 298039 | D33: 2124380 | E33: =C33-D33 | F33: =F34+E33 | G33: 338144645 | H33: 79200 | I33: 897000 | J33: =H33-I33 | K33: =K34+J33 | L33: 54984756 | M33: 608193 | N33: 5380500 | O33: =M33-N33 | P33: =P34+O33 | Q33: 539477902 | R33: 2475579 | S33: 3474400 | T33: =R33-S33 | U33: =U34+T33 | V33: 113436141
B34: 46239 | C34: 2229200 | D34: 2002479 | E34: =C34-D34 | F34: =F35+E34 | G34: 337063545 | H34: 214300 | I34: 3455062 | J34: =H34-I34 | K34: =K35+J34 | L34: 54218315 | M34: 44300 | N34: 3894700 | O34: =M34-N34 | P34: =P35+O34 | Q34: 535903484 | R34: 2435301 | S34: 2871171 | T34: =R34-S34 | U34: =U35+T34 | V34: 111380552
B35: 46238 | C35: 773600 | D35: 1854700 | E35: =C35-D35 | F35: =F36+E35 | G35: 335836919 | H35: 62300 | I35: 828741 | J35: =H35-I35 | K35: =K36+J35 | L35: 53239815 | M35: 79650 | N35: 3654068 | O35: =M35-N35 | P35: =P36+O35 | Q35: 532928674 | R35: 290950 | S35: 2346539 | T35: =R35-S35 | U35: =U36+T35 | V35: 108968652
B36: 46237 | C36: 698150 | D36: 1267097 | E36: =C36-D36 | F36: =F37+E36 | G36: 333182264 | H36: 688700 | I36: 1667200 | J36: =H36-I36 | K36: =K37+J36 | L36: 52575415 | M36: 379100 | N36: 2610210 | O36: =M36-N36 | P36: =P37+O36 | Q36: 530191474 | R36: 470800 | S36: 2882700 | T36: =R36-S36 | U36: =U37+T36 | V36: 106513712
B37: 46234 | C37: 418604 | D37: 3073259 | E37: =C37-D37 | F37: =F38+E37 | H37: 213300 | I37: 877700 | J37: =H37-I37 | K37: =K38+J37 | M37: 248700 | N37: 2985900 | O37: =M37-N37 | P37: =P38+O37 | R37: 923760 | S37: 3378700 | T37: =R37-S37 | U37: =U38+T37
B38: 46233 | C38: 1287680 | D38: 4113654 | E38: =C38-D38 | F38: =F39+E38 | G38: 328304174 | H38: 63500 | I38: 239500 | J38: =H38-I38 | K38: =K39+J38 | L38: 51798615 | M38: 710600 | N38: 1511200 | O38: =M38-N38 | P38: =P39+O38 | Q38: 527790301 | R38: 5859140 | S38: 10836780 | T38: =R38-S38 | U38: =U39+T38 | V38: 99818737
B39: 46232 | C39: 729667 | D39: 2781783 | E39: =C39-D39 | F39: =F40+E39 | G39: 328304174 | H39: 79200 | I39: 680000 | J39: =H39-I39 | K39: =K40+J39 | L39: 51798615 | M39: 132127 | N39: 1732700 | O39: =M39-N39 | P39: =P40+O39 | Q39: 525496201 | R39: 1275919 | S39: 2993254 | T39: =R39-S39 | U39: =U40+T39 | V39: 98392567
B40: 46231 | C40: 1974000 | D40: 1806800 | E40: =C40-D40 | F40: =F41+E40 | G40: 326218909 | H40: 719600 | I40: 455670 | J40: =H40-I40 | K40: =K41+J40 | L40: 50999314 | M40: 557349 | N40: 2851449 | O40: =M40-N40 | P40: =P41+O40 | Q40: 521512940 | R40: 6579550 | S40: 8005720 | T40: =R40-S40 | U40: =U41+T40 | V40: 95836152
B41: 46230 | C41: 2638000 | D41: 4646465 | E41: =C41-D41 | F41: =F42+E41 | G41: 324385797 | H41: 107800 | I41: 873501 | J41: =H41-I41 | K41: =K42+J41 | L41: 50316044 | M41: 83330 | N41: 3984991 | O41: =M41-N41 | P41: =P42+O41 | Q41: 518384550 | R41: 578041 | S41: 3072056 | T41: =R41-S41 | U41: =U42+T41 | V41: 93199283
B42: 46227 | C42: 1493401 | D42: 3534613 | E42: =C42-D42 | F42: =F43+E42 | H42: 180800 | I42: 1136400 | J42: =H42-I42 | K42: =K43+J42 | M42: 636410 | N42: 3801100 | O42: =M42-N42 | P42: =P43+O42 | R42: 1655531 | S42: 4292400 | T42: =R42-S42 | U42: =U43+T42
B43: 46226 | C43: 2263500 | D43: 2951495 | E43: =C43-D43 | F43: =F44+E43 | G43: 315242287 | H43: 777200 | I43: 75900 | J43: =H43-I43 | K43: =K44+J43 | L43: 42592763 | M43: 688700 | N43: 4114500 | O43: =M43-N43 | P43: =P44+O43 | Q43: 508569050 | R43: 1398700 | S43: 5467900 | T43: =R43-S43 | U43: =U44+T43 | V43: 86893103
B44: 46225 | C44: 976540 | D44: 9463555 | E44: =C44-D44 | F44: =F45+E44 | G44: 312368653 | H44: 1417000 | I44: 9154281 | J44: =H44-I44 | K44: =K45+J44 | L44: 43245363 | M44: 1075500 | N44: 7497500 | O44: =M44-N44 | P44: =P45+O44 | Q44: 507857950 | R44: 1406420 | S44: 3643400 | T44: =R44-S44 | U44: =U45+T44 | V44: 84914903
...

Sheet Sheet2
A4: Ngày | B4: ACB | C4: VIB | D4: VPB | E4: TCB | H4: ACB | I4: VIB | J4: VPB | K4: TCB
A5: 46276 | B5: -262721036 | C5: -53598471 | D5: -146857711 | E5: -121214897 | G5: Tháng 3 | H5: =IFERROR(SUMIFS(Sheet1!$E$10:$E$5000,Sheet1!$B$10:$B$5000,">="&DATE(YEAR(MAX(Sheet1!$B$10:$B$5000)),VALUE(SUBSTITUTE($G5,"Tháng ","")),1),Sheet1!$B$10:$B$5000,"<"&EDATE(DATE(YEAR(MAX(Sheet1!$B$10:$B$5000)),VALUE(SUBSTITUTE($G5,"Tháng ","")),1),1)),0) | I5: =IFERROR(SUMIFS(Sheet1!$J$10:$J$5000,Sheet1!$B$10:$B$5000,">="&DATE(YEAR(MAX(Sheet1!$B$10:$B$5000)),VALUE(SUBSTITUTE($G5,"Tháng ","")),1),Sheet1!$B$10:$B$5000,"<"&EDATE(DATE(YEAR(MAX(Sheet1!$B$10:$B$5000)),VALUE(SUBSTITUTE($G5,"Tháng ","")),1),1)),0) | J5: =IFERROR(SUMIFS(Sheet1!$O$10:$O$5000,Sheet1!$B$10:$B$5000,">="&DATE(YEAR(MAX(Sheet1!$B$10:$B$5000)),VALUE(SUBSTITUTE($G5,"Tháng ","")),1),Sheet1!$B$10:$B$5000,"<"&EDATE(DATE(YEAR(MAX(Sheet1!$B$10:$B$5000)),VALUE(SUBSTITUTE($G5,"Tháng ","")),1),1)),0) | K5: =IFERROR(SUMIFS(Sheet1!$T$10:$T$5000,Sheet1!$B$10:$B$5000,">="&DATE(YEAR(MAX(Sheet1!$B$10:$B$5000)),VALUE(SUBSTITUTE($G5,"Tháng ","")),1),Sheet1!$B$10:$B$5000,"<"&EDATE(DATE(YEAR(MAX(Sheet1!$B$10:$B$5000)),VALUE(SUBSTITUTE($G5,"Tháng ","")),1),1)),0)
A6: 46275 | B6: -261740523 | C6: -53386316 | D6: -142016896 | E6: -122272076 | G6: Tháng 4 | H6: =IFERROR(SUMIFS(Sheet1!$E$10:$E$5000,Sheet1!$B$10:$B$5000,">="&DATE(YEAR(MAX(Sheet1!$B$10:$B$5000)),VALUE(SUBSTITUTE($G6,"Tháng ","")),1),Sheet1!$B$10:$B$5000,"<"&EDATE(DATE(YEAR(MAX(Sheet1!$B$10:$B$5000)),VALUE(SUBSTITUTE($G6,"Tháng ","")),1),1)),0) | I6: =IFERROR(SUMIFS(Sheet1!$J$10:$J$5000,Sheet1!$B$10:$B$5000,">="&DATE(YEAR(MAX(Sheet1!$B$10:$B$5000)),VALUE(SUBSTITUTE($G6,"Tháng ","")),1),Sheet1!$B$10:$B$5000,"<"&EDATE(DATE(YEAR(MAX(Sheet1!$B$10:$B$5000)),VALUE(SUBSTITUTE($G6,"Tháng ","")),1),1)),0) | J6: =IFERROR(SUMIFS(Sheet1!$O$10:$O$5000,Sheet1!$B$10:$B$5000,">="&DATE(YEAR(MAX(Sheet1!$B$10:$B$5000)),VALUE(SUBSTITUTE($G6,"Tháng ","")),1),Sheet1!$B$10:$B$5000,"<"&EDATE(DATE(YEAR(MAX(Sheet1!$B$10:$B$5000)),VALUE(SUBSTITUTE($G6,"Tháng ","")),1),1)),0) | K6: =IFERROR(SUMIFS(Sheet1!$T$10:$T$5000,Sheet1!$B$10:$B$5000,">="&DATE(YEAR(MAX(Sheet1!$B$10:$B$5000)),VALUE(SUBSTITUTE($G6,"Tháng ","")),1),Sheet1!$B$10:$B$5000,"<"&EDATE(DATE(YEAR(MAX(Sheet1!$B$10:$B$5000)),VALUE(SUBSTITUTE($G6,"Tháng ","")),1),1)),0)
A7: 46274 | B7: -262288292 | C7: -53299281 | D7: -143055092 | E7: -123221976 | G7: Tháng 5 | H7: =IFERROR(SUMIFS(Sheet1!$E$10:$E$5000,Sheet1!$B$10:$B$5000,">="&DATE(YEAR(MAX(Sheet1!$B$10:$B$5000)),VALUE(SUBSTITUTE($G7,"Tháng ","")),1),Sheet1!$B$10:$B$5000,"<"&EDATE(DATE(YEAR(MAX(Sheet1!$B$10:$B$5000)),VALUE(SUBSTITUTE($G7,"Tháng ","")),1),1)),0) | I7: =IFERROR(SUMIFS(Sheet1!$J$10:$J$5000,Sheet1!$B$10:$B$5000,">="&DATE(YEAR(MAX(Sheet1!$B$10:$B$5000)),VALUE(SUBSTITUTE($G7,"Tháng ","")),1),Sheet1!$B$10:$B$5000,"<"&EDATE(DATE(YEAR(MAX(Sheet1!$B$10:$B$5000)),VALUE(SUBSTITUTE($G7,"Tháng ","")),1),1)),0) | J7: =IFERROR(SUMIFS(Sheet1!$O$10:$O$5000,Sheet1!$B$10:$B$5000,">="&DATE(YEAR(MAX(Sheet1!$B$10:$B$5000)),VALUE(SUBSTITUTE($G7,"Tháng ","")),1),Sheet1!$B$10:$B$5000,"<"&EDATE(DATE(YEAR(MAX(Sheet1!$B$10:$B$5000)),VALUE(SUBSTITUTE($G7,"Tháng ","")),1),1)),0) | K7: =IFERROR(SUMIFS(Sheet1!$T$10:$T$5000,Sheet1!$B$10:$B$5000,">="&DATE(YEAR(MAX(Sheet1!$B$10:$B$5000)),VALUE(SUBSTITUTE($G7,"Tháng ","")),1),Sheet1!$B$10:$B$5000,"<"&EDATE(DATE(YEAR(MAX(Sheet1!$B$10:$B$5000)),VALUE(SUBSTITUTE($G7,"Tháng ","")),1),1)),0)
A8: 46273 | B8: -261580192 | C8: -55249581 | D8: -141227292 | E8: -126529244 | G8: Tháng 6 | H8: =IFERROR(SUMIFS(Sheet1!$E$10:$E$5000,Sheet1!$B$10:$B$5000,">="&DATE(YEAR(MAX(Sheet1!$B$10:$B$5000)),VALUE(SUBSTITUTE($G8,"Tháng ","")),1),Sheet1!$B$10:$B$5000,"<"&EDATE(DATE(YEAR(MAX(Sheet1!$B$10:$B$5000)),VALUE(SUBSTITUTE($G8,"Tháng ","")),1),1)),0) | I8: =IFERROR(SUMIFS(Sheet1!$J$10:$J$5000,Sheet1!$B$10:$B$5000,">="&DATE(YEAR(MAX(Sheet1!$B$10:$B$5000)),VALUE(SUBSTITUTE($G8,"Tháng ","")),1),Sheet1!$B$10:$B$5000,"<"&EDATE(DATE(YEAR(MAX(Sheet1!$B$10:$B$5000)),VALUE(SUBSTITUTE($G8,"Tháng ","")),1),1)),0) | J8: =IFERROR(SUMIFS(Sheet1!$O$10:$O$5000,Sheet1!$B$10:$B$5000,">="&DATE(YEAR(MAX(Sheet1!$B$10:$B$5000)),VALUE(SUBSTITUTE($G8,"Tháng ","")),1),Sheet1!$B$10:$B$5000,"<"&EDATE(DATE(YEAR(MAX(Sheet1!$B$10:$B$5000)),VALUE(SUBSTITUTE($G8,"Tháng ","")),1),1)),0) | K8: =IFERROR(SUMIFS(Sheet1!$T$10:$T$5000,Sheet1!$B$10:$B$5000,">="&DATE(YEAR(MAX(Sheet1!$B$10:$B$5000)),VALUE(SUBSTITUTE($G8,"Tháng ","")),1),Sheet1!$B$10:$B$5000,"<"&EDATE(DATE(YEAR(MAX(Sheet1!$B$10:$B$5000)),VALUE(SUBSTITUTE($G8,"Tháng ","")),1),1)),0)
A9: 46272 | B9: -261927904 | C9: -58071513 | D9: -138393645 | E9: -126375411 | G9: Tháng 7 | H9: =IFERROR(SUMIFS(Sheet1!$E$10:$E$5000,Sheet1!$B$10:$B$5000,">="&DATE(YEAR(MAX(Sheet1!$B$10:$B$5000)),VALUE(SUBSTITUTE($G9,"Tháng ","")),1),Sheet1!$B$10:$B$5000,"<"&EDATE(DATE(YEAR(MAX(Sheet1!$B$10:$B$5000)),VALUE(SUBSTITUTE($G9,"Tháng ","")),1),1)),0) | I9: =IFERROR(SUMIFS(Sheet1!$J$10:$J$5000,Sheet1!$B$10:$B$5000,">="&DATE(YEAR(MAX(Sheet1!$B$10:$B$5000)),VALUE(SUBSTITUTE($G9,"Tháng ","")),1),Sheet1!$B$10:$B$5000,"<"&EDATE(DATE(YEAR(MAX(Sheet1!$B$10:$B$5000)),VALUE(SUBSTITUTE($G9,"Tháng ","")),1),1)),0) | J9: =IFERROR(SUMIFS(Sheet1!$O$10:$O$5000,Sheet1!$B$10:$B$5000,">="&DATE(YEAR(MAX(Sheet1!$B$10:$B$5000)),VALUE(SUBSTITUTE($G9,"Tháng ","")),1),Sheet1!$B$10:$B$5000,"<"&EDATE(DATE(YEAR(MAX(Sheet1!$B$10:$B$5000)),VALUE(SUBSTITUTE($G9,"Tháng ","")),1),1)),0) | K9: =IFERROR(SUMIFS(Sheet1!$T$10:$T$5000,Sheet1!$B$10:$B$5000,">="&DATE(YEAR(MAX(Sheet1!$B$10:$B$5000)),VALUE(SUBSTITUTE($G9,"Tháng ","")),1),Sheet1!$B$10:$B$5000,"<"&EDATE(DATE(YEAR(MAX(Sheet1!$B$10:$B$5000)),VALUE(SUBSTITUTE($G9,"Tháng ","")),1),1)),0)
A10: 46269 | B10: -261836464 | C10: -57584513 | D10: -139632825 | E10: -125877341 | G10: Tháng 8 | H10: =IFERROR(SUMIFS(Sheet1!$E$10:$E$5000,Sheet1!$B$10:$B$5000,">="&DATE(YEAR(MAX(Sheet1!$B$10:$B$5000)),VALUE(SUBSTITUTE($G10,"Tháng ","")),1),Sheet1!$B$10:$B$5000,"<"&EDATE(DATE(YEAR(MAX(Sheet1!$B$10:$B$5000)),VALUE(SUBSTITUTE($G10,"Tháng ","")),1),1)),0) | I10: =IFERROR(SUMIFS(Sheet1!$J$10:$J$5000,Sheet1!$B$10:$B$5000,">="&DATE(YEAR(MAX(Sheet1!$B$10:$B$5000)),VALUE(SUBSTITUTE($G10,"Tháng ","")),1),Sheet1!$B$10:$B$5000,"<"&EDATE(DATE(YEAR(MAX(Sheet1!$B$10:$B$5000)),VALUE(SUBSTITUTE($G10,"Tháng ","")),1),1)),0) | J10: =IFERROR(SUMIFS(Sheet1!$O$10:$O$5000,Sheet1!$B$10:$B$5000,">="&DATE(YEAR(MAX(Sheet1!$B$10:$B$5000)),VALUE(SUBSTITUTE($G10,"Tháng ","")),1),Sheet1!$B$10:$B$5000,"<"&EDATE(DATE(YEAR(MAX(Sheet1!$B$10:$B$5000)),VALUE(SUBSTITUTE($G10,"Tháng ","")),1),1)),0) | K10: =IFERROR(SUMIFS(Sheet1!$T$10:$T$5000,Sheet1!$B$10:$B$5000,">="&DATE(YEAR(MAX(Sheet1!$B$10:$B$5000)),VALUE(SUBSTITUTE($G10,"Tháng ","")),1),Sheet1!$B$10:$B$5000,"<"&EDATE(DATE(YEAR(MAX(Sheet1!$B$10:$B$5000)),VALUE(SUBSTITUTE($G10,"Tháng ","")),1),1)),0)
A11: 46268 | B11: -259424996 | C11: -59560513 | D11: -143162925 | E11: -126178341 | G11: Tháng 9 | H11: =IFERROR(SUMIFS(Sheet1!$E$10:$E$5000,Sheet1!$B$10:$B$5000,">="&DATE(YEAR(MAX(Sheet1!$B$10:$B$5000)),VALUE(SUBSTITUTE($G11,"Tháng ","")),1),Sheet1!$B$10:$B$5000,"<"&EDATE(DATE(YEAR(MAX(Sheet1!$B$10:$B$5000)),VALUE(SUBSTITUTE($G11,"Tháng ","")),1),1)),0) | I11: =IFERROR(SUMIFS(Sheet1!$J$10:$J$5000,Sheet1!$B$10:$B$5000,">="&DATE(YEAR(MAX(Sheet1!$B$10:$B$5000)),VALUE(SUBSTITUTE($G11,"Tháng ","")),1),Sheet1!$B$10:$B$5000,"<"&EDATE(DATE(YEAR(MAX(Sheet1!$B$10:$B$5000)),VALUE(SUBSTITUTE($G11,"Tháng ","")),1),1)),0) | J11: =IFERROR(SUMIFS(Sheet1!$O$10:$O$5000,Sheet1!$B$10:$B$5000,">="&DATE(YEAR(MAX(Sheet1!$B$10:$B$5000)),VALUE(SUBSTITUTE($G11,"Tháng ","")),1),Sheet1!$B$10:$B$5000,"<"&EDATE(DATE(YEAR(MAX(Sheet1!$B$10:$B$5000)),VALUE(SUBSTITUTE($G11,"Tháng ","")),1),1)),0) | K11: =IFERROR(SUMIFS(Sheet1!$T$10:$T$5000,Sheet1!$B$10:$B$5000,">="&DATE(YEAR(MAX(Sheet1!$B$10:$B$5000)),VALUE(SUBSTITUTE($G11,"Tháng ","")),1),Sheet1!$B$10:$B$5000,"<"&EDATE(DATE(YEAR(MAX(Sheet1!$B$10:$B$5000)),VALUE(SUBSTITUTE($G11,"Tháng ","")),1),1)),0)
A12: 46262 | B12: -255746144 | C12: -59442513 | D12: -136805703 | E12: -121418011 | G12: Từ đầu năm | H12: =IFERROR(SUMIFS(Sheet1!$E$10:$E$5000,Sheet1!$B$10:$B$5000,">="&DATE(YEAR(MAX(Sheet1!$B$10:$B$5000)),1,1),Sheet1!$B$10:$B$5000,"<="&MAX(Sheet1!$B$10:$B$5000)),0) | I12: =IFERROR(SUMIFS(Sheet1!$J$10:$J$5000,Sheet1!$B$10:$B$5000,">="&DATE(YEAR(MAX(Sheet1!$B$10:$B$5000)),1,1),Sheet1!$B$10:$B$5000,"<="&MAX(Sheet1!$B$10:$B$5000)),0) | J12: =IFERROR(SUMIFS(Sheet1!$O$10:$O$5000,Sheet1!$B$10:$B$5000,">="&DATE(YEAR(MAX(Sheet1!$B$10:$B$5000)),1,1),Sheet1!$B$10:$B$5000,"<="&MAX(Sheet1!$B$10:$B$5000)),0) | K12: =IFERROR(SUMIFS(Sheet1!$T$10:$T$5000,Sheet1!$B$10:$B$5000,">="&DATE(YEAR(MAX(Sheet1!$B$10:$B$5000)),1,1),Sheet1!$B$10:$B$5000,"<="&MAX(Sheet1!$B$10:$B$5000)),0)
A13: 46261 | B13: -256495518 | C13: -59056713 | D13: -140876157 | E13: -127803903
A14: 46260 | B14: -256761848 | C14: -58117213 | D14: -144632957 | E14: -140834302
A15: 46259 | B15: -253266947 | C15: -58748908 | D15: -144267366 | E15: -144838602
A16: 46258 | B16: -251637499 | C16: -58774204 | D16: -144572665 | E16: -141691242
A17: 46255 | B17: -251648160 | C17: -58587404 | D17: -147122948 | E17: -142441470
A18: 46254 | B18: -252253270 | C18: -59104304 | D18: -144995548 | E18: -142435545
A19: 46253 | B19: -250925594 | C19: -59093391 | D19: -141502699 | E19: -142710899
A20: 46252 | B20: -248490772 | C20: -58845113 | D20: -137528720 | E20: -143183271
A21: 46251 | B21: -247412377 | C21: -58401713 | D21: -132791020 | E21: -143487171
A22: 46248 | B22: -243042795 | C22: -58617113 | D22: -131973120 | E22: -145360756
A23: 46247 | B23: -241493624 | C23: -58274312 | D23: -130360620 | E23: -148204387
A24: 46246 | B24: -237363355 | C24: -58444912 | D24: -129105741 | E24: -142850551
... A172: 46028 | B172: -1857800 | C172: 9506 | D172: 5853957 | E172: -2868820
A173: 46027
