Workbook

Sheet Danh mục
A1: STT | B1: Mã | C1: Giá đóng cửa | D1: % Thay đổi giá | I1: P/E | J1: PB | K1: So với P/E Trung vị 5 năm | L1: So với P/B Trung vị 5 năm | M1: 52w high | N1: 52w low | O1: P/E Tvi 5y | P1: P/B Tvi 5y
D2: 1 tuần | E2: 1 tháng | F2: YTD | G2: 52w High | H2: 52w Low
C3: VNĐ | D3: % | E3: % | F3: % | G3: % | H3: % | I3: Lần | J3: Lần | K3: % | L3: %
A4: 64 | B4: PNJ | C4: =VLOOKUP($B4,'Cập nhật giá'!$B$9:$Q$1603,4,FALSE()) -> 36000 | D4: =VLOOKUP($B4,'Cập nhật giá'!$B$9:$Q$1603,8,FALSE()) -> 0.16129032 | E4: =VLOOKUP($B4,'Cập nhật giá'!$B$9:$Q$1603,9,FALSE()) -> -0.29133858 | F4: =VLOOKUP($B4,'Cập nhật giá'!$B$9:$Q$1603,10,FALSE()) -> -0.43793095 | G4: =C4/M4-1 -> -0.57482441 | H4: =C4/N4-1 -> 0.17073171 | I4: =VLOOKUP($B4,'Cập nhật giá'!$B$9:$Q$1603,11,FALSE()) -> 6.35 | J4: =VLOOKUP($B4,'Cập nhật giá'!$B$9:$Q$1603,12,FALSE()) -> 1.33 | K4: =I4/O4-1 -> -0.57723036 | L4: =J4/P4-1 -> -0.55960265 | M4: =VLOOKUP($B4,'Cập nhật giá'!$B$9:$Q$1603,13,FALSE()) -> 84670.9 | N4: =VLOOKUP($B4,'Cập nhật giá'!$B$9:$Q$1603,14,FALSE()) -> 30750 | O4: =VLOOKUP($B4,'Cập nhật giá'!$B$9:$Q$1603,15,FALSE()) -> 15.02 | P4: =VLOOKUP($B4,'Cập nhật giá'!$B$9:$Q$1603,16,FALSE()) -> 3.02
A5: 39 | B5: DGC | C5: =VLOOKUP($B5,'Cập nhật giá'!$B$9:$Q$1603,4,FALSE()) -> 44200 | D5: =VLOOKUP($B5,'Cập nhật giá'!$B$9:$Q$1603,8,FALSE()) -> 0.13043478 | E5: =VLOOKUP($B5,'Cập nhật giá'!$B$9:$Q$1603,9,FALSE()) -> -0.035986914 | F5: =VLOOKUP($B5,'Cập nhật giá'!$B$9:$Q$1603,10,FALSE()) -> -0.35474453 | G5: =C5/M5-1 -> -0.57244697 | H5: =C5/N5-1 -> 0.22777778 | I5: =VLOOKUP($B5,'Cập nhật giá'!$B$9:$Q$1603,11,FALSE()) -> 7.86 | J5: =VLOOKUP($B5,'Cập nhật giá'!$B$9:$Q$1603,12,FALSE()) -> 1.06 | K5: =I5/O5-1 -> -0.29348315 | L5: =J5/P5-1 -> -0.64309764 | M5: =VLOOKUP($B5,'Cập nhật giá'!$B$9:$Q$1603,13,FALSE()) -> 103378.99 | N5: =VLOOKUP($B5,'Cập nhật giá'!$B$9:$Q$1603,14,FALSE()) -> 36000 | O5: =VLOOKUP($B5,'Cập nhật giá'!$B$9:$Q$1603,15,FALSE()) -> 11.125 | P5: =VLOOKUP($B5,'Cập nhật giá'!$B$9:$Q$1603,16,FALSE()) -> 2.97
A6: 33 | B6: PLX | C6: =VLOOKUP($B6,'Cập nhật giá'!$B$9:$Q$1603,4,FALSE()) -> 35950 | D6: =VLOOKUP($B6,'Cập nhật giá'!$B$9:$Q$1603,8,FALSE()) -> 0.11827178 | E6: =VLOOKUP($B6,'Cập nhật giá'!$B$9:$Q$1603,9,FALSE()) -> 0.067004309 | F6: =VLOOKUP($B6,'Cập nhật giá'!$B$9:$Q$1603,10,FALSE()) -> 0.054913609 | G6: =C6/M6-1 -> -0.46419496 | H6: =C6/N6-1 -> 0.14053447 | I6: =VLOOKUP($B6,'Cập nhật giá'!$B$9:$Q$1603,11,FALSE()) -> 14.18 | J6: =VLOOKUP($B6,'Cập nhật giá'!$B$9:$Q$1603,12,FALSE()) -> 1.77 | K6: =I6/O6-1 -> -0.32217973 | L6: =J6/P6-1 -> -0.092307692 | M6: =VLOOKUP($B6,'Cập nhật giá'!$B$9:$Q$1603,13,FALSE()) -> 67095.3 | N6: =VLOOKUP($B6,'Cập nhật giá'!$B$9:$Q$1603,14,FALSE()) -> 31520.31 | O6: =VLOOKUP($B6,'Cập nhật giá'!$B$9:$Q$1603,15,FALSE()) -> 20.92 | P6: =VLOOKUP($B6,'Cập nhật giá'!$B$9:$Q$1603,16,FALSE()) -> 1.95
A7: 57 | B7: GEX | C7: =VLOOKUP($B7,'Cập nhật giá'!$B$9:$Q$1603,4,FALSE()) -> 24550 | D7: =VLOOKUP($B7,'Cập nhật giá'!$B$9:$Q$1603,8,FALSE()) -> 0.091111111 | E7: =VLOOKUP($B7,'Cập nhật giá'!$B$9:$Q$1603,9,FALSE()) -> -0.16354344 | F7: =VLOOKUP($B7,'Cập nhật giá'!$B$9:$Q$1603,10,FALSE()) -> -0.18359664 | G7: =C7/M7-1 -> -0.4557311 | H7: =C7/N7-1 -> 0.20935961 | I7: =VLOOKUP($B7,'Cập nhật giá'!$B$9:$Q$1603,11,FALSE()) -> 23.42 | J7: =VLOOKUP($B7,'Cập nhật giá'!$B$9:$Q$1603,12,FALSE()) -> 1.62 | K7: =I7/O7-1 -> -0.02599293 | L7: =J7/P7-1 -> 0.018867925 | M7: =VLOOKUP($B7,'Cập nhật giá'!$B$9:$Q$1603,13,FALSE()) -> 45106.38 | N7: =VLOOKUP($B7,'Cập nhật giá'!$B$9:$Q$1603,14,FALSE()) -> 20300 | O7: =VLOOKUP($B7,'Cập nhật giá'!$B$9:$Q$1603,15,FALSE()) -> 24.045 | P7: =VLOOKUP($B7,'Cập nhật giá'!$B$9:$Q$1603,16,FALSE()) -> 1.59
A8: 10 | B8: GAS | C8: =VLOOKUP($B8,'Cập nhật giá'!$B$9:$Q$1603,4,FALSE()) -> 74600 | D8: =VLOOKUP($B8,'Cập nhật giá'!$B$9:$Q$1603,8,FALSE()) -> 0.087463557 | E8: =VLOOKUP($B8,'Cập nhật giá'!$B$9:$Q$1603,9,FALSE()) -> 0.010840108 | F8: =VLOOKUP($B8,'Cập nhật giá'!$B$9:$Q$1603,10,FALSE()) -> 0.03038674 | G8: =C8/M8-1 -> -0.42035742 | H8: =C8/N8-1 -> 0.33214286 | I8: =VLOOKUP($B8,'Cập nhật giá'!$B$9:$Q$1603,11,FALSE()) -> 14.17 | J8: =VLOOKUP($B8,'Cập nhật giá'!$B$9:$Q$1603,12,FALSE()) -> 2.62 | K8: =I8/O8-1 -> -0.088452879 | L8: =J8/P8-1 -> -0.093425606 | M8: =VLOOKUP($B8,'Cập nhật giá'!$B$9:$Q$1603,13,FALSE()) -> 128700 | N8: =VLOOKUP($B8,'Cập nhật giá'!$B$9:$Q$1603,14,FALSE()) -> 56000 | O8: =VLOOKUP($B8,'Cập nhật giá'!$B$9:$Q$1603,15,FALSE()) -> 15.545 | P8: =VLOOKUP($B8,'Cập nhật giá'!$B$9:$Q$1603,16,FALSE()) -> 2.89
A9: 38 | B9: GVR | C9: =VLOOKUP($B9,'Cập nhật giá'!$B$9:$Q$1603,4,FALSE()) -> 29750 | D9: =VLOOKUP($B9,'Cập nhật giá'!$B$9:$Q$1603,8,FALSE()) -> 0.081818182 | E9: =VLOOKUP($B9,'Cập nhật giá'!$B$9:$Q$1603,9,FALSE()) -> -0.054054054 | F9: =VLOOKUP($B9,'Cập nhật giá'!$B$9:$Q$1603,10,FALSE()) -> 0.13549618 | G9: =C9/M9-1 -> -0.34972678 | H9: =C9/N9-1 -> 0.19506804 | I9: =VLOOKUP($B9,'Cập nhật giá'!$B$9:$Q$1603,11,FALSE()) -> 16.69 | J9: =VLOOKUP($B9,'Cập nhật giá'!$B$9:$Q$1603,12,FALSE()) -> 1.96 | K9: =I9/O9-1 -> -0.35955487 | L9: =J9/P9-1 -> -0.096774194 | M9: =VLOOKUP($B9,'Cập nhật giá'!$B$9:$Q$1603,13,FALSE()) -> 45750 | N9: =VLOOKUP($B9,'Cập nhật giá'!$B$9:$Q$1603,14,FALSE()) -> 24893.98 | O9: =VLOOKUP($B9,'Cập nhật giá'!$B$9:$Q$1603,15,FALSE()) -> 26.06 | P9: =VLOOKUP($B9,'Cập nhật giá'!$B$9:$Q$1603,16,FALSE()) -> 2.17
A10: 68 | B10: BCM | C10: =VLOOKUP($B10,'Cập nhật giá'!$B$9:$Q$1603,4,FALSE()) -> 38600 | D10: =VLOOKUP($B10,'Cập nhật giá'!$B$9:$Q$1603,8,FALSE()) -> 0.081232493 | E10: =VLOOKUP($B10,'Cập nhật giá'!$B$9:$Q$1603,9,FALSE()) -> -0.23865878 | F10: =VLOOKUP($B10,'Cập nhật giá'!$B$9:$Q$1603,10,FALSE()) -> -0.36460278 | G10: =C10/M10-1 -> -0.50915565 | H10: =C10/N10-1 -> 0.10285714 | I10: =VLOOKUP($B10,'Cập nhật giá'!$B$9:$Q$1603,11,FALSE()) -> 18.68 | J10: =VLOOKUP($B10,'Cập nhật giá'!$B$9:$Q$1603,12,FALSE()) -> 1.83 | K10: =I10/O10-1 -> -0.35296155 | L10: =J10/P10-1 -> -0.51004016 | M10: =VLOOKUP($B10,'Cập nhật giá'!$B$9:$Q$1603,13,FALSE()) -> 78640 | N10: =VLOOKUP($B10,'Cập nhật giá'!$B$9:$Q$1603,14,FALSE()) -> 35000 | O10: =VLOOKUP($B10,'Cập nhật giá'!$B$9:$Q$1603,15,FALSE()) -> 28.87 | P10: =VLOOKUP($B10,'Cập nhật giá'!$B$9:$Q$1603,16,FALSE()) -> 3.735
A11: 36 | B11: DGW | C11: =VLOOKUP($B11,'Cập nhật giá'!$B$9:$Q$1603,4,FALSE()) -> 39400 | D11: =VLOOKUP($B11,'Cập nhật giá'!$B$9:$Q$1603,8,FALSE()) -> 0.076502732 | E11: =VLOOKUP($B11,'Cập nhật giá'!$B$9:$Q$1603,9,FALSE()) -> 0 | F11: =VLOOKUP($B11,'Cập nhật giá'!$B$9:$Q$1603,10,FALSE()) -> 0.034780713 | G11: =C11/M11-1 -> -0.27934915 | H11: =C11/N11-1 -> 0.18853695 | I11: =VLOOKUP($B11,'Cập nhật giá'!$B$9:$Q$1603,11,FALSE()) -> 10.41 | J11: =VLOOKUP($B11,'Cập nhật giá'!$B$9:$Q$1603,12,FALSE()) -> 2.34 | K11: =I11/O11-1 -> -0.43607801 | L11: =J11/P11-1 -> -0.2972973 | M11: =VLOOKUP($B11,'Cập nhật giá'!$B$9:$Q$1603,13,FALSE()) -> 54672.8 | N11: =VLOOKUP($B11,'Cập nhật giá'!$B$9:$Q$1603,14,FALSE()) -> 33150 | O11: =VLOOKUP($B11,'Cập nhật giá'!$B$9:$Q$1603,15,FALSE()) -> 18.46 | P11: =VLOOKUP($B11,'Cập nhật giá'!$B$9:$Q$1603,16,FALSE()) -> 3.33
A12: 8 | B12: NVL | C12: =VLOOKUP($B12,'Cập nhật giá'!$B$9:$Q$1603,4,FALSE()) -> 13900 | D12: =VLOOKUP($B12,'Cập nhật giá'!$B$9:$Q$1603,8,FALSE()) -> 0.069230769 | E12: =VLOOKUP($B12,'Cập nhật giá'!$B$9:$Q$1603,9,FALSE()) -> 0.10756972 | F12: =VLOOKUP($B12,'Cập nhật giá'!$B$9:$Q$1603,10,FALSE()) -> 0.11932757 | G12: =C12/M12-1 -> -0.27107205 | H12: =C12/N12-1 -> 0.42314505 | I12: =VLOOKUP($B12,'Cập nhật giá'!$B$9:$Q$1603,11,FALSE()) -> 8.18 | J12: =VLOOKUP($B12,'Cập nhật giá'!$B$9:$Q$1603,12,FALSE()) -> 0.69 | K12: =I12/O12-1 -> -0.48063492 | L12: =J12/P12-1 -> -0.12658228 | M12: =VLOOKUP($B12,'Cập nhật giá'!$B$9:$Q$1603,13,FALSE()) -> 19069.1 | N12: =VLOOKUP($B12,'Cập nhật giá'!$B$9:$Q$1603,14,FALSE()) -> 9767.1 | O12: =VLOOKUP($B12,'Cập nhật giá'!$B$9:$Q$1603,15,FALSE()) -> 15.75 | P12: =VLOOKUP($B12,'Cập nhật giá'!$B$9:$Q$1603,16,FALSE()) -> 0.79
A13: 32 | B13: DIG | C13: =VLOOKUP($B13,'Cập nhật giá'!$B$9:$Q$1603,4,FALSE()) -> 10700 | D13: =VLOOKUP($B13,'Cập nhật giá'!$B$9:$Q$1603,8,FALSE()) -> 0.064676617 | E13: =VLOOKUP($B13,'Cập nhật giá'!$B$9:$Q$1603,9,FALSE()) -> -0.10084034 | F13: =VLOOKUP($B13,'Cập nhật giá'!$B$9:$Q$1603,10,FALSE()) -> -0.36119403 | G13: =C13/M13-1 -> -0.56504065 | H13: =C13/N13-1 -> 0.10423117 | I13: =VLOOKUP($B13,'Cập nhật giá'!$B$9:$Q$1603,11,FALSE()) -> 10.18 | J13: =VLOOKUP($B13,'Cập nhật giá'!$B$9:$Q$1603,12,FALSE()) -> 0.84 | K13: =I13/O13-1 -> -0.80600286 | L13: =J13/P13-1 -> -0.56020942 | M13: =VLOOKUP($B13,'Cập nhật giá'!$B$9:$Q$1603,13,FALSE()) -> 24600 | N13: =VLOOKUP($B13,'Cập nhật giá'!$B$9:$Q$1603,14,FALSE()) -> 9690 | O13: =VLOOKUP($B13,'Cập nhật giá'!$B$9:$Q$1603,15,FALSE()) -> 52.475 | P13: =VLOOKUP($B13,'Cập nhật giá'!$B$9:$Q$1603,16,FALSE()) -> 1.91
A14: 30 | B14: FRT | C14: =VLOOKUP($B14,'Cập nhật giá'!$B$9:$Q$1603,4,FALSE()) -> 132000 | D14: =VLOOKUP($B14,'Cập nhật giá'!$B$9:$Q$1603,8,FALSE()) -> 0.061093248 | E14: =VLOOKUP($B14,'Cập nhật giá'!$B$9:$Q$1603,9,FALSE()) -> 0.12820513 | F14: =VLOOKUP($B14,'Cập nhật giá'!$B$9:$Q$1603,10,FALSE()) -> -0.07292824 | G14: =C14/M14-1 -> -0.2102722 | H14: =C14/N14-1 -> 0.25714286 | I14: =VLOOKUP($B14,'Cập nhật giá'!$B$9:$Q$1603,11,FALSE()) -> 20.76 | J14: =VLOOKUP($B14,'Cập nhật giá'!$B$9:$Q$1603,12,FALSE()) -> 4.92 | K14: =I14/O14-1 -> -0.12901196 | L14: =J14/P14-1 -> -0.28643945 | M14: =VLOOKUP($B14,'Cập nhật giá'!$B$9:$Q$1603,13,FALSE()) -> 167146.2 | N14: =VLOOKUP($B14,'Cập nhật giá'!$B$9:$Q$1603,14,FALSE()) -> 105000 | O14: =VLOOKUP($B14,'Cập nhật giá'!$B$9:$Q$1603,15,FALSE()) -> 23.835 | P14: =VLOOKUP($B14,'Cập nhật giá'!$B$9:$Q$1603,16,FALSE()) -> 6.895
A15: 54 | B15: CTG | C15: =VLOOKUP($B15,'Cập nhật giá'!$B$9:$Q$1603,4,FALSE()) -> 32500 | D15: =VLOOKUP($B15,'Cập nhật giá'!$B$9:$Q$1603,8,FALSE()) -> 0.055194805 | E15: =VLOOKUP($B15,'Cập nhật giá'!$B$9:$Q$1603,9,FALSE()) -> -0.036448914 | F15: =VLOOKUP($B15,'Cập nhật giá'!$B$9:$Q$1603,10,FALSE()) -> -0.076877631 | G15: =C15/M15-1 -> -0.20478013 | H15: =C15/N15-1 -> 0.13043478 | I15: =VLOOKUP($B15,'Cập nhật giá'!$B$9:$Q$1603,11,FALSE()) -> 6.28 | J15: =VLOOKUP($B15,'Cập nhật giá'!$B$9:$Q$1603,12,FALSE()) -> 1.27 | K15: =I15/O15-1 -> -0.27981651 | L15: =J15/P15-1 -> -0.086330935 | M15: =VLOOKUP($B15,'Cập nhật giá'!$B$9:$Q$1603,13,FALSE()) -> 40869.2 | N15: =VLOOKUP($B15,'Cập nhật giá'!$B$9:$Q$1603,14,FALSE()) -> 28750 | O15: =VLOOKUP($B15,'Cập nhật giá'!$B$9:$Q$1603,15,FALSE()) -> 8.72 | P15: =VLOOKUP($B15,'Cập nhật giá'!$B$9:$Q$1603,16,FALSE()) -> 1.39
... A73: 7 | B73: PC1 | C73: =VLOOKUP($B73,'Cập nhật giá'!$B$9:$Q$1603,4,FALSE()) -> 20650 | D73: =VLOOKUP($B73,'Cập nhật giá'!$B$9:$Q$1603,8,FALSE()) -> -0.035046729 | E73: =VLOOKUP($B73,'Cập nhật giá'!$B$9:$Q$1603,9,FALSE()) -> -0.043981481 | F73: =VLOOKUP($B73,'Cập nhật giá'!$B$9:$Q$1603,10,FALSE()) -> -0.084257206 | G73: =C73/M73-1 -> -0.34130781 | H73: =C73/N73-1 -> 0.16997167 | I73: =VLOOKUP($B73,'Cập nhật giá'!$B$9:$Q$1603,11,FALSE()) -> 7.22 | J73: =VLOOKUP($B73,'Cập nhật giá'!$B$9:$Q$1603,12,FALSE()) -> 1.27 | K73: =I73/O73-1 -> -0.58481886 | L73: =J73/P73-1 -> -0.19620253 | M73: =VLOOKUP($B73,'Cập nhật giá'!$B$9:$Q$1603,13,FALSE()) -> 31350 | N73: =VLOOKUP($B73,'Cập nhật giá'!$B$9:$Q$1603,14,FALSE()) -> 17650 | O73: =VLOOKUP($B73,'Cập nhật giá'!$B$9:$Q$1603,15,FALSE()) -> 17.39 | P73: =VLOOKUP($B73,'Cập nhật giá'!$B$9:$Q$1603,16,FALSE()) -> 1.58

Sheet Cập nhật giá
A5: Tính năng | B5: DE - Doanh nghiệp
A6: Ngày trích xuất
A8: STT | B8: Mã | C8: Tên công ty | D8: Sàn | E8: Giá đóng cửa điều chỉnh (D) Ngày: Hôm nay Đơn vị: VND | F8: Giá đóng cửa điều chỉnh (D) Ngày: 1 tuần trước Đơn vị: VND | G8: Giá đóng cửa điều chỉnh (D) Ngày: 1 tháng trước Đơn vị: VND | H8: Giá đóng cửa điều chỉnh (D) Ngày: 31/12/2025 Đơn vị: VND | I8: % tuần | J8: % tháng | K8: % ytd | L8: P/E pha loãng Chỉ số TTM Đơn vị: Lần | M8: P/B Chỉ số TTM Đơn vị: Lần | N8: Giá cao nhất 52 tuần Đơn vị: VND | O8: Giá thấp nhất 52 tuần Đơn vị: VND | P8: P/E Trung vị 5 năm Đơn vị: Lần | Q8: P/B Trung vị 5 năm Đơn vị: Lần
A9: 1 | B9: AG1 | C9: 28.1 JSC | D9: UPCoM | E9: 11400 | F9: 10945 | G9: 10722 | H9: 10845.8 | I9: =$E9/F9-1 -> 0.041571494 | J9: =$E9/G9-1 -> 0.063234471 | K9: =$E9/H9-1 -> 0.051098121 | L9: 4.97 | M9: 0.95 | N9: 12090.4 | O9: 9864.34
A10: 2 | B10: MT9 | C10: 319 Miền Trung | D10: UPCoM | I10: =$E10/F10-1 -> #DIV/0! | J10: =$E10/G10-1 -> #DIV/0! | K10: =$E10/H10-1 -> #DIV/0!
A11: 3 | B11: NBB | C11: 577 CORP | D11: HOSE | E11: 17300 | F11: 17300 | G11: 17450 | H11: 19500 | I11: =$E11/F11-1 -> 0 | J11: =$E11/G11-1 -> -0.0085959885 | K11: =$E11/H11-1 -> -0.11282051 | L11: 182.09 | M11: 0.96 | N11: 26800 | O11: 16100
A12: 4 | B12: AAV | C12: AAV Group | D12: UPCoM | E12: 6367 | F12: 6452 | G12: 6828 | H12: 6300 | I12: =$E12/F12-1 -> -0.01317421 | J12: =$E12/G12-1 -> -0.06751611 | K12: =$E12/H12-1 -> 0.010634921 | L12: -20.33 | M12: 0.62 | N12: 9000 | O12: 5400
A13: 5 | B13: ACB | C13: ACB | D13: HOSE | E13: 22400 | F13: 21900 | G13: 22600 | H13: 20678.4 | I13: =$E13/F13-1 -> 0.02283105 | J13: =$E13/G13-1 -> -0.0088495575 | K13: =$E13/H13-1 -> 0.083255958 | L13: 8.29 | M13: 1.31 | N13: 25374.12 | O13: 18696.72 | P13: 6.93 | Q13: 1.42
A14: 6 | B14: AGR | C14: Agriseco | D14: HOSE | E14: 13050 | F14: 12900 | G14: 16000 | H14: 16100 | I14: =$E14/F14-1 -> 0.011627907 | J14: =$E14/G14-1 -> -0.184375 | K14: =$E14/H14-1 -> -0.18944099 | L14: 17.38 | M14: 1.13 | N14: 20550 | O14: 12250
A15: 7 | B15: AAA | C15: An Phát Bioplastics | D15: HOSE | E15: 7150 | F15: 7110 | G15: 7186.5 | H15: 7550.62 | I15: =$E15/F15-1 -> 0.005625879 | J15: =$E15/G15-1 -> -0.0050789675 | K15: =$E15/H15-1 -> -0.053057895 | L15: 5.15 | M15: 0.5 | N15: 8480.07 | O15: 6410.36
A16: 8 | B16: HII | C16: An Tiến Industries | D16: HOSE | E16: 8600 | F16: 7090 | G16: 5900 | H16: 5852.34 | I16: =$E16/F16-1 -> 0.21297602 | J16: =$E16/G16-1 -> 0.45762712 | K16: =$E16/H16-1 -> 0.46949767 | L16: 2.7 | M16: 0.57 | N16: 8850 | O16: 4329.78
A17: 9 | B17: VNS | C17: Ánh Dương Việt Nam | D17: HOSE | E17: 7390 | F17: 7500 | G17: 7830 | H17: 9100 | I17: =$E17/F17-1 -> -0.014666667 | J17: =$E17/G17-1 -> -0.056194125 | K17: =$E17/H17-1 -> -0.18791209 | L17: 446.42 | M17: 0.45 | N17: 9830 | O17: 7390
A18: 10 | B18: AMP | C18: Armephaco | D18: UPCoM | E18: 15500 | F18: 16000 | G18: 14500 | H18: 14700 | I18: =$E18/F18-1 -> -0.03125 | J18: =$E18/G18-1 -> 0.068965517 | K18: =$E18/H18-1 -> 0.054421769 | L18: 26.81 | M18: 0.96 | N18: 16500 | O18: 11000
A19: 11 | B19: ATG | C19: ATG Planet | D19: UPCoM | E19: 8100 | F19: 8133 | G19: 8600 | H19: 9500 | I19: =$E19/F19-1 -> -0.0040575433 | J19: =$E19/G19-1 -> -0.058139535 | K19: =$E19/H19-1 -> -0.14736842 | L19: 3.48 | M19: 13.93 | N19: 11500 | O19: 5500
A20: 12 | B20: TSB | C20: Ắc quy Tia Sáng | D20: HNX | E20: 21200 | F20: 20100 | G20: 21300 | H20: 27800 | I20: =$E20/F20-1 -> 0.054726368 | J20: =$E20/G20-1 -> -0.0046948357 | K20: =$E20/H20-1 -> -0.23741007 | L20: -103.41 | M20: 1.93 | N20: 41000 | O20: 18700
A21: 13 | B21: BCG | C21: Bamboo Capital | D21: UPCoM | E21: 2500 | F21: 2500 | G21: 2530 | H21: 2530 | I21: =$E21/F21-1 -> 0 | J21: =$E21/G21-1 -> -0.011857708 | K21: =$E21/H21-1 -> -0.011857708 | L21: 4.7 | M21: 0.22 | N21: 3890 | O21: 2500
A22: 14 | B22: DBM | C22: BAMEPHARM | D22: UPCoM | E22: 31177 | F22: 29000 | G22: 25706.88 | H22: 23921.68 | I22: =$E22/F22-1 -> 0.075068966 | J22: =$E22/G22-1 -> 0.21278817 | K22: =$E22/H22-1 -> 0.30329475 | L22: 13.03 | M22: 0.87 | N22: 31177 | O22: 18744.6
A23: 15 | B23: ECI | C23: Bản đồ và tranh ảnh GD | D23: HNX | E23: 9200 | F23: 9200 | G23: 9200 | H23: 9500 | I23: =$E23/F23-1 -> 0 | J23: =$E23/G23-1 -> 0 | K23: =$E23/H23-1 -> -0.031578947 | L23: -33.98 | M23: 0.53 | N23: 16200 | O23: 7200
A24: 16 | B24: FRT | C24: Bán lẻ FPT | D24: HOSE | E24: 132000 | F24: 124400 | G24: 117000 | H24: 142383.8 | I24: =$E24/F24-1 -> 0.061093248 | J24: =$E24/G24-1 -> 0.12820513 | K24: =$E24/H24-1 -> -0.07292824 | L24: 20.76 | M24: 4.92 | N24: 167146.2 | O24: 105000 | P24: 23.835 | Q24: 6.895
A25: 17 | B25: HCO | C25: Bánh kẹo Hải Châu | D25: UPCoM | I25: =$E25/F25-1 -> #DIV/0! | J25: =$E25/G25-1 -> #DIV/0! | K25: =$E25/H25-1 -> #DIV/0!
A26: 18 | B26: HHC | C26: Bánh kẹo Hải Hà | D26: HNX | E26: 74700 | F26: 74200 | G26: 74500 | H26: 149700 | I26: =$E26/F26-1 -> 0.0067385445 | J26: =$E26/G26-1 -> 0.0026845638 | K26: =$E26/H26-1 -> -0.501002 | L26: 22.5 | M26: 1.8 | N26: 167000 | O26: 67700
A27: 19 | B27: HNF | C27: Bánh kẹo Hữu Nghị | D27: UPCoM | E27: 23400 | F27: 23400 | G27: 24000 | H27: 32017.52 | I27: =$E27/F27-1 -> 0 | J27: =$E27/G27-1 -> -0.025 | K27: =$E27/H27-1 -> -0.26915014 | L27: 6.93 | M27: 1.05 | N27: 34272.28 | O27: 20500
A28: 20 | B28: SGC | C28: Bánh phồng tôm Sa Giang | D28: HNX | E28: 104100 | F28: 106000 | G28: 106100 | H28: 82000 | I28: =$E28/F28-1 -> -0.017924528 | J28: =$E28/G28-1 -> -0.018850141 | K28: =$E28/H28-1 -> 0.2695122 | L28: 5.66 | M28: 1.42 | N28: 113800 | O28: 75400
A29: 21 | B29: BAL | C29: Bao bì Balpac | D29: UPCoM | E29: 7500 | F29: 7500 | G29: 7100 | H29: 9500 | I29: =$E29/F29-1 -> 0 | J29: =$E29/G29-1 -> 0.056338028 | K29: =$E29/H29-1 -> -0.21052632 | L29: 9.67 | M29: 0.49 | N29: 10426.9 | O29: 6200
A30: 22 | B30: BPC | C30: Bao bì Bỉm Sơn | D30: HNX | E30: 12500 | F30: 12500 | G30: 12500 | H30: 12300 | I30: =$E30/F30-1 -> 0 | J30: =$E30/G30-1 -> 0 | K30: =$E30/H30-1 -> 0.016260163 | L30: 22.69 | M30: 0.5 | N30: 14583.92 | O30: 10149.62
A31: 23 | B31: PBP | C31: Bao bì Dầu khí VN | D31: HNX | E31: 11400 | F31: 11700 | G31: 11200 | H31: 12600 | I31: =$E31/F31-1 -> -0.025641026 | J31: =$E31/G31-1 -> 0.017857143 | K31: =$E31/H31-1 -> -0.095238095 | L31: 6.86 | M31: 0.75 | N31: 13500 | O31: 11100
A32: 24 | B32: PMP | C32: Bao bì Đạm Phú Mỹ | D32: HNX | E32: 12000 | F32: 12000 | G32: 12000 | H32: 12500 | I32: =$E32/F32-1 -> 0 | J32: =$E32/G32-1 -> 0 | K32: =$E32/H32-1 -> -0.04 | L32: 5.53 | M32: 0.66 | N32: 14932.8 | O32: 11500
A33: 25 | B33: BBH | C33: Bao bì Hoàng Thạch | D33: UPCoM | E33: 9000 | F33: 8447 | G33: 7719 | H33: 13412.22 | I33: =$E33/F33-1 -> 0.06546703 | J33: =$E33/G33-1 -> 0.16595414 | K33: =$E33/H33-1 -> -0.32897015 | L33: 25.38 | M33: 0.25 | N33: 16522.3 | O33: 6839
A34: 26 | B34: HPB | C34: Bao bì PP | D34: UPCoM | E34: 18500 | F34: 18100 | G34: 20000 | H34: 14733.56 | I34: =$E34/F34-1 -> 0.022099448 | J34: =$E34/G34-1 -> -0.075 | K34: =$E34/H34-1 -> 0.25563679 | L34: 8.21 | M34: 0.51 | N34: 37744.56 | O34: 11833.87
A35: 27 | B35: HBD | C35: Bao bì PP Bình Dương | D35: UPCoM | E35: 26000 | F35: 26400 | G35: 25500 | H35: 17751.7 | I35: =$E35/F35-1 -> -0.015151515 | J35: =$E35/G35-1 -> 0.019607843 | K35: =$E35/H35-1 -> 0.46464846 | L35: 12.45 | M35: 1.35 | N35: 26400 | O35: 15415.95
A36: 28 | B36: TKA | C36: Bao bì Tân Khánh An | D36: UPCoM | E36: 3000 | F36: 3000 | G36: 3000 | H36: 3000 | I36: =$E36/F36-1 -> 0 | J36: =$E36/G36-1 -> 0 | K36: =$E36/H36-1 -> 0 | L36: 1.09 | M36: 0.2 | N36: 3000 | O36: 2965.46
A37: 29 | B37: BTG | C37: Bao bì Tiền Giang | D37: UPCoM | E37: 8100 | F37: 8100 | G37: 8100 | H37: 7600 | I37: =$E37/F37-1 -> 0 | J37: =$E37/G37-1 -> 0 | K37: =$E37/H37-1 -> 0.065789474 | L37: -5.86 | M37: 0.62 | N37: 10300 | O37: 7600
... A62: 54 | B62: LEC | C62: BĐS Điện lực Miền Trung | D62: UPCoM | E62: 4500 | F62: 4500 | G62: 5000 | H62: 3300 | I62: =$E62/F62-1 -> 0 | J62: =$E62/G62-1 -> -0.1 | K62: =$E62/H62-1 -> 0.36363636 | L62: -5.62 | M62: 0.52 | N62: 5806 | O62: 3100
A63: 55 | B63: NLG | C63: BĐS Nam Long | D63: HOSE | E63: 22200 | F63: 22200 | G63: 25650 | H63: 29874.5 | I63: =$E63/F63-1 -> 0 | J63: =$E63/G63-1 -> -0.13450292 | K63: =$E63/H63-1 -> -0.25689133 | L63: 15.77 | M63: 0.86 | N63: 42252.15 | O63: 20000 | P63: 21.32 | Q63: 1.58
A64: 56 | B64: PDR | C64: BĐS Phát Đạt | D64: HOSE | E64: 11900 | F64: 11450 | G64: 14300 | H64: 18800 | I64: =$E64/F64-1 -> 0.03930131 | J64: =$E64/G64-1 -> -0.16783217 | K64: =$E64/H64-1 -> -0.36702128 | L64: 19.22 | M64: 0.94 | N64: 26300 | O64: 11150 | P64: 27.94 | Q64: 1.79
A65: 57 | B65: LSG | C65: BĐS Sài Gòn Vina | D65: UPCoM | E65: 35075 | F65: 32497 | G65: 33565 | H65: 32297 | I65: =$E65/F65-1 -> 0.0793304 | J65: =$E65/G65-1 -> 0.044987338 | K65: =$E65/H65-1 -> 0.086014181 | L65: 46.35 | M65: 2.86 | N65: 38833 | O65: 19870
A66: 58 | B66: PPI | C66: BĐS Thái Bình Dương | D66: UPCoM | E66: 400 | F66: 400 | G66: 400 | H66: 400 | I66: =$E66/F66-1 -> 0 | J66: =$E66/G66-1 -> 0 | K66: =$E66/H66-1 -> 0 | L66: -5.72 | M66: -0.13 | N66: 400 | O66: 400
A67: 59 | B67: BCM | C67: Becamex Group | D67: HOSE | E67: 38600 | F67: 35700 | G67: 50700 | H67: 60749.4 | I67: =$E67/F67-1 -> 0.081232493 | J67: =$E67/G67-1 -> -0.23865878 | K67: =$E67/H67-1 -> -0.36460278 | L67: 18.68 | M67: 1.83 | N67: 78640 | O67: 35000 | P67: 28.87 | Q67: 3.735
A68: 60 | B68: IJC | C68: Becamex IJC | D68: HOSE | E68: 7420 | F68: 7180 | G68: 8630 | H68: 10186.7 | I68: =$E68/F68-1 -> 0.033426184 | J68: =$E68/G68-1 -> -0.14020857 | K68: =$E68/H68-1 -> -0.27159924 | L68: 6.22 | M68: 0.59 | N68: 13455.92 | O68: 6690 | P68: 9.225 | Q68: 1.03
A69: 61 | B69: TDC | C69: Becamex TDC | D69: HOSE | E69: 7250 | F69: 7070 | G69: 9170 | H69: 10887.86 | I69: =$E69/F69-1 -> 0.025459689 | J69: =$E69/G69-1 -> -0.20937841 | K69: =$E69/H69-1 -> -0.33412075 | L69: 4.21 | M69: 0.53 | N69: 13379.15 | O69: 6870
...
