Workbook

Sheet Danh mục
A1: STT | B1: Mã | C1: Giá đóng cửa | D1: % Thay đổi giá | I1: P/E | J1: PB | K1: So với P/E Trung vị 5 năm | L1: So với P/B Trung vị 5 năm | M1: 52w high | N1: 52w low | O1: P/E Tvi 5y | P1: P/B Tvi 5y
D2: 1 tuần | E2: 1 tháng | F2: YTD | G2: 52w High | H2: 52w Low
C3: VNĐ | D3: % | E3: % | F3: % | G3: % | H3: % | I3: Lần | J3: Lần | K3: % | L3: %
A4: 1 | B4: BCM | C4: =VLOOKUP($B4,'Cập nhật giá'!$B$9:$Q$1603,4,FALSE) | D4: =VLOOKUP($B4,'Cập nhật giá'!$B$9:$Q$1603,8,FALSE) | E4: =VLOOKUP($B4,'Cập nhật giá'!$B$9:$Q$1603,9,FALSE) | F4: =VLOOKUP($B4,'Cập nhật giá'!$B$9:$Q$1603,10,FALSE) | G4: =C4/M4-1 | H4: =C4/N4-1 | I4: =VLOOKUP($B4,'Cập nhật giá'!$B$9:$Q$1603,11,FALSE) | J4: =VLOOKUP($B4,'Cập nhật giá'!$B$9:$Q$1603,12,FALSE) | K4: =I4/O4-1 | L4: =J4/P4-1 | M4: =VLOOKUP($B4,'Cập nhật giá'!$B$9:$Q$1603,13,FALSE) | N4: =VLOOKUP($B4,'Cập nhật giá'!$B$9:$Q$1603,14,FALSE) | O4: =VLOOKUP($B4,'Cập nhật giá'!$B$9:$Q$1603,15,FALSE) | P4: =VLOOKUP($B4,'Cập nhật giá'!$B$9:$Q$1603,16,FALSE)
A5: 2 | B5: PVT | C5: =VLOOKUP($B5,'Cập nhật giá'!$B$9:$Q$1603,4,FALSE) | D5: =VLOOKUP($B5,'Cập nhật giá'!$B$9:$Q$1603,8,FALSE) | E5: =VLOOKUP($B5,'Cập nhật giá'!$B$9:$Q$1603,9,FALSE) | F5: =VLOOKUP($B5,'Cập nhật giá'!$B$9:$Q$1603,10,FALSE) | G5: =C5/M5-1 | H5: =C5/N5-1 | I5: =VLOOKUP($B5,'Cập nhật giá'!$B$9:$Q$1603,11,FALSE) | J5: =VLOOKUP($B5,'Cập nhật giá'!$B$9:$Q$1603,12,FALSE) | K5: =I5/O5-1 | L5: =J5/P5-1 | M5: =VLOOKUP($B5,'Cập nhật giá'!$B$9:$Q$1603,13,FALSE) | N5: =VLOOKUP($B5,'Cập nhật giá'!$B$9:$Q$1603,14,FALSE) | O5: =VLOOKUP($B5,'Cập nhật giá'!$B$9:$Q$1603,15,FALSE) | P5: =VLOOKUP($B5,'Cập nhật giá'!$B$9:$Q$1603,16,FALSE)
A6: 3 | B6: FRT | C6: =VLOOKUP($B6,'Cập nhật giá'!$B$9:$Q$1603,4,FALSE) | D6: =VLOOKUP($B6,'Cập nhật giá'!$B$9:$Q$1603,8,FALSE) | E6: =VLOOKUP($B6,'Cập nhật giá'!$B$9:$Q$1603,9,FALSE) | F6: =VLOOKUP($B6,'Cập nhật giá'!$B$9:$Q$1603,10,FALSE) | G6: =C6/M6-1 | H6: =C6/N6-1 | I6: =VLOOKUP($B6,'Cập nhật giá'!$B$9:$Q$1603,11,FALSE) | J6: =VLOOKUP($B6,'Cập nhật giá'!$B$9:$Q$1603,12,FALSE) | K6: =I6/O6-1 | L6: =J6/P6-1 | M6: =VLOOKUP($B6,'Cập nhật giá'!$B$9:$Q$1603,13,FALSE) | N6: =VLOOKUP($B6,'Cập nhật giá'!$B$9:$Q$1603,14,FALSE) | O6: =VLOOKUP($B6,'Cập nhật giá'!$B$9:$Q$1603,15,FALSE) | P6: =VLOOKUP($B6,'Cập nhật giá'!$B$9:$Q$1603,16,FALSE)
A7: 4 | B7: TCB | C7: =VLOOKUP($B7,'Cập nhật giá'!$B$9:$Q$1603,4,FALSE) | D7: =VLOOKUP($B7,'Cập nhật giá'!$B$9:$Q$1603,8,FALSE) | E7: =VLOOKUP($B7,'Cập nhật giá'!$B$9:$Q$1603,9,FALSE) | F7: =VLOOKUP($B7,'Cập nhật giá'!$B$9:$Q$1603,10,FALSE) | G7: =C7/M7-1 | H7: =C7/N7-1 | I7: =VLOOKUP($B7,'Cập nhật giá'!$B$9:$Q$1603,11,FALSE) | J7: =VLOOKUP($B7,'Cập nhật giá'!$B$9:$Q$1603,12,FALSE) | K7: =I7/O7-1 | L7: =J7/P7-1 | M7: =VLOOKUP($B7,'Cập nhật giá'!$B$9:$Q$1603,13,FALSE) | N7: =VLOOKUP($B7,'Cập nhật giá'!$B$9:$Q$1603,14,FALSE) | O7: =VLOOKUP($B7,'Cập nhật giá'!$B$9:$Q$1603,15,FALSE) | P7: =VLOOKUP($B7,'Cập nhật giá'!$B$9:$Q$1603,16,FALSE)
A8: 5 | B8: DXG | C8: =VLOOKUP($B8,'Cập nhật giá'!$B$9:$Q$1603,4,FALSE) | D8: =VLOOKUP($B8,'Cập nhật giá'!$B$9:$Q$1603,8,FALSE) | E8: =VLOOKUP($B8,'Cập nhật giá'!$B$9:$Q$1603,9,FALSE) | F8: =VLOOKUP($B8,'Cập nhật giá'!$B$9:$Q$1603,10,FALSE) | G8: =C8/M8-1 | H8: =C8/N8-1 | I8: =VLOOKUP($B8,'Cập nhật giá'!$B$9:$Q$1603,11,FALSE) | J8: =VLOOKUP($B8,'Cập nhật giá'!$B$9:$Q$1603,12,FALSE) | K8: =I8/O8-1 | L8: =J8/P8-1 | M8: =VLOOKUP($B8,'Cập nhật giá'!$B$9:$Q$1603,13,FALSE) | N8: =VLOOKUP($B8,'Cập nhật giá'!$B$9:$Q$1603,14,FALSE) | O8: =VLOOKUP($B8,'Cập nhật giá'!$B$9:$Q$1603,15,FALSE) | P8: =VLOOKUP($B8,'Cập nhật giá'!$B$9:$Q$1603,16,FALSE)
A9: 6 | B9: VHC | C9: =VLOOKUP($B9,'Cập nhật giá'!$B$9:$Q$1603,4,FALSE) | D9: =VLOOKUP($B9,'Cập nhật giá'!$B$9:$Q$1603,8,FALSE) | E9: =VLOOKUP($B9,'Cập nhật giá'!$B$9:$Q$1603,9,FALSE) | F9: =VLOOKUP($B9,'Cập nhật giá'!$B$9:$Q$1603,10,FALSE) | G9: =C9/M9-1 | H9: =C9/N9-1 | I9: =VLOOKUP($B9,'Cập nhật giá'!$B$9:$Q$1603,11,FALSE) | J9: =VLOOKUP($B9,'Cập nhật giá'!$B$9:$Q$1603,12,FALSE) | K9: =I9/O9-1 | L9: =J9/P9-1 | M9: =VLOOKUP($B9,'Cập nhật giá'!$B$9:$Q$1603,13,FALSE) | N9: =VLOOKUP($B9,'Cập nhật giá'!$B$9:$Q$1603,14,FALSE) | O9: =VLOOKUP($B9,'Cập nhật giá'!$B$9:$Q$1603,15,FALSE) | P9: =VLOOKUP($B9,'Cập nhật giá'!$B$9:$Q$1603,16,FALSE)
A10: 7 | B10: OCB | C10: =VLOOKUP($B10,'Cập nhật giá'!$B$9:$Q$1603,4,FALSE) | D10: =VLOOKUP($B10,'Cập nhật giá'!$B$9:$Q$1603,8,FALSE) | E10: =VLOOKUP($B10,'Cập nhật giá'!$B$9:$Q$1603,9,FALSE) | F10: =VLOOKUP($B10,'Cập nhật giá'!$B$9:$Q$1603,10,FALSE) | G10: =C10/M10-1 | H10: =C10/N10-1 | I10: =VLOOKUP($B10,'Cập nhật giá'!$B$9:$Q$1603,11,FALSE) | J10: =VLOOKUP($B10,'Cập nhật giá'!$B$9:$Q$1603,12,FALSE) | K10: =I10/O10-1 | L10: =J10/P10-1 | M10: =VLOOKUP($B10,'Cập nhật giá'!$B$9:$Q$1603,13,FALSE) | N10: =VLOOKUP($B10,'Cập nhật giá'!$B$9:$Q$1603,14,FALSE) | O10: =VLOOKUP($B10,'Cập nhật giá'!$B$9:$Q$1603,15,FALSE) | P10: =VLOOKUP($B10,'Cập nhật giá'!$B$9:$Q$1603,16,FALSE)
A11: 8 | B11: DGW | C11: =VLOOKUP($B11,'Cập nhật giá'!$B$9:$Q$1603,4,FALSE) | D11: =VLOOKUP($B11,'Cập nhật giá'!$B$9:$Q$1603,8,FALSE) | E11: =VLOOKUP($B11,'Cập nhật giá'!$B$9:$Q$1603,9,FALSE) | F11: =VLOOKUP($B11,'Cập nhật giá'!$B$9:$Q$1603,10,FALSE) | G11: =C11/M11-1 | H11: =C11/N11-1 | I11: =VLOOKUP($B11,'Cập nhật giá'!$B$9:$Q$1603,11,FALSE) | J11: =VLOOKUP($B11,'Cập nhật giá'!$B$9:$Q$1603,12,FALSE) | K11: =I11/O11-1 | L11: =J11/P11-1 | M11: =VLOOKUP($B11,'Cập nhật giá'!$B$9:$Q$1603,13,FALSE) | N11: =VLOOKUP($B11,'Cập nhật giá'!$B$9:$Q$1603,14,FALSE) | O11: =VLOOKUP($B11,'Cập nhật giá'!$B$9:$Q$1603,15,FALSE) | P11: =VLOOKUP($B11,'Cập nhật giá'!$B$9:$Q$1603,16,FALSE)
A12: 9 | B12: GVR | C12: =VLOOKUP($B12,'Cập nhật giá'!$B$9:$Q$1603,4,FALSE) | D12: =VLOOKUP($B12,'Cập nhật giá'!$B$9:$Q$1603,8,FALSE) | E12: =VLOOKUP($B12,'Cập nhật giá'!$B$9:$Q$1603,9,FALSE) | F12: =VLOOKUP($B12,'Cập nhật giá'!$B$9:$Q$1603,10,FALSE) | G12: =C12/M12-1 | H12: =C12/N12-1 | I12: =VLOOKUP($B12,'Cập nhật giá'!$B$9:$Q$1603,11,FALSE) | J12: =VLOOKUP($B12,'Cập nhật giá'!$B$9:$Q$1603,12,FALSE) | K12: =I12/O12-1 | L12: =J12/P12-1 | M12: =VLOOKUP($B12,'Cập nhật giá'!$B$9:$Q$1603,13,FALSE) | N12: =VLOOKUP($B12,'Cập nhật giá'!$B$9:$Q$1603,14,FALSE) | O12: =VLOOKUP($B12,'Cập nhật giá'!$B$9:$Q$1603,15,FALSE) | P12: =VLOOKUP($B12,'Cập nhật giá'!$B$9:$Q$1603,16,FALSE)
A13: 10 | B13: VGC | C13: =VLOOKUP($B13,'Cập nhật giá'!$B$9:$Q$1603,4,FALSE) | D13: =VLOOKUP($B13,'Cập nhật giá'!$B$9:$Q$1603,8,FALSE) | E13: =VLOOKUP($B13,'Cập nhật giá'!$B$9:$Q$1603,9,FALSE) | F13: =VLOOKUP($B13,'Cập nhật giá'!$B$9:$Q$1603,10,FALSE) | G13: =C13/M13-1 | H13: =C13/N13-1 | I13: =VLOOKUP($B13,'Cập nhật giá'!$B$9:$Q$1603,11,FALSE) | J13: =VLOOKUP($B13,'Cập nhật giá'!$B$9:$Q$1603,12,FALSE) | K13: =I13/O13-1 | L13: =J13/P13-1 | M13: =VLOOKUP($B13,'Cập nhật giá'!$B$9:$Q$1603,13,FALSE) | N13: =VLOOKUP($B13,'Cập nhật giá'!$B$9:$Q$1603,14,FALSE) | O13: =VLOOKUP($B13,'Cập nhật giá'!$B$9:$Q$1603,15,FALSE) | P13: =VLOOKUP($B13,'Cập nhật giá'!$B$9:$Q$1603,16,FALSE)
A14: 11 | B14: NLG | C14: =VLOOKUP($B14,'Cập nhật giá'!$B$9:$Q$1603,4,FALSE) | D14: =VLOOKUP($B14,'Cập nhật giá'!$B$9:$Q$1603,8,FALSE) | E14: =VLOOKUP($B14,'Cập nhật giá'!$B$9:$Q$1603,9,FALSE) | F14: =VLOOKUP($B14,'Cập nhật giá'!$B$9:$Q$1603,10,FALSE) | G14: =C14/M14-1 | H14: =C14/N14-1 | I14: =VLOOKUP($B14,'Cập nhật giá'!$B$9:$Q$1603,11,FALSE) | J14: =VLOOKUP($B14,'Cập nhật giá'!$B$9:$Q$1603,12,FALSE) | K14: =I14/O14-1 | L14: =J14/P14-1 | M14: =VLOOKUP($B14,'Cập nhật giá'!$B$9:$Q$1603,13,FALSE) | N14: =VLOOKUP($B14,'Cập nhật giá'!$B$9:$Q$1603,14,FALSE) | O14: =VLOOKUP($B14,'Cập nhật giá'!$B$9:$Q$1603,15,FALSE) | P14: =VLOOKUP($B14,'Cập nhật giá'!$B$9:$Q$1603,16,FALSE)
A15: 12 | B15: MWG | C15: =VLOOKUP($B15,'Cập nhật giá'!$B$9:$Q$1603,4,FALSE) | D15: =VLOOKUP($B15,'Cập nhật giá'!$B$9:$Q$1603,8,FALSE) | E15: =VLOOKUP($B15,'Cập nhật giá'!$B$9:$Q$1603,9,FALSE) | F15: =VLOOKUP($B15,'Cập nhật giá'!$B$9:$Q$1603,10,FALSE) | G15: =C15/M15-1 | H15: =C15/N15-1 | I15: =VLOOKUP($B15,'Cập nhật giá'!$B$9:$Q$1603,11,FALSE) | J15: =VLOOKUP($B15,'Cập nhật giá'!$B$9:$Q$1603,12,FALSE) | K15: =I15/O15-1 | L15: =J15/P15-1 | M15: =VLOOKUP($B15,'Cập nhật giá'!$B$9:$Q$1603,13,FALSE) | N15: =VLOOKUP($B15,'Cập nhật giá'!$B$9:$Q$1603,14,FALSE) | O15: =VLOOKUP($B15,'Cập nhật giá'!$B$9:$Q$1603,15,FALSE) | P15: =VLOOKUP($B15,'Cập nhật giá'!$B$9:$Q$1603,16,FALSE)
... A73: 70 | B73: VIC | C73: =VLOOKUP($B73,'Cập nhật giá'!$B$9:$Q$1603,4,FALSE) | D73: =VLOOKUP($B73,'Cập nhật giá'!$B$9:$Q$1603,8,FALSE) | E73: =VLOOKUP($B73,'Cập nhật giá'!$B$9:$Q$1603,9,FALSE) | F73: =VLOOKUP($B73,'Cập nhật giá'!$B$9:$Q$1603,10,FALSE) | G73: =C73/M73-1 | H73: =C73/N73-1 | I73: =VLOOKUP($B73,'Cập nhật giá'!$B$9:$Q$1603,11,FALSE) | J73: =VLOOKUP($B73,'Cập nhật giá'!$B$9:$Q$1603,12,FALSE) | K73: =I73/O73-1 | L73: =J73/P73-1 | M73: =VLOOKUP($B73,'Cập nhật giá'!$B$9:$Q$1603,13,FALSE) | N73: =VLOOKUP($B73,'Cập nhật giá'!$B$9:$Q$1603,14,FALSE) | O73: =VLOOKUP($B73,'Cập nhật giá'!$B$9:$Q$1603,15,FALSE) | P73: =VLOOKUP($B73,'Cập nhật giá'!$B$9:$Q$1603,16,FALSE)

Sheet Cập nhật giá
A5: Tính năng | B5: DE - Doanh nghiệp
A6: Ngày trích xuất
A8: STT | B8: Mã | C8: Tên công ty | D8: Sàn | E8: Giá đóng cửa điều chỉnh (D) Ngày: Hôm nay Đơn vị: VND | F8: Giá đóng cửa điều chỉnh (D) Ngày: 1 tuần trước Đơn vị: VND | G8: Giá đóng cửa điều chỉnh (D) Ngày: 1 tháng trước Đơn vị: VND | H8: Giá đóng cửa điều chỉnh (D) Ngày: 31/12/2025 Đơn vị: VND | I8: % tuần | J8: % tháng | K8: % ytd | L8: P/E pha loãng Chỉ số TTM Đơn vị: Lần | M8: P/B Chỉ số TTM Đơn vị: Lần | N8: Giá cao nhất 52 tuần Đơn vị: VND | O8: Giá thấp nhất 52 tuần Đơn vị: VND | P8: P/E Trung vị 5 năm Đơn vị: Lần | Q8: P/B Trung vị 5 năm Đơn vị: Lần
A9: 1 | B9: AG1 | C9: 28.1 JSC | D9: UPCoM | E9: 11500 | F9: 11400 | G9: 10800 | H9: 10845.8 | I9: =$E9/F9-1 | J9: =$E9/G9-1 | K9: =$E9/H9-1 | L9: 5.01 | M9: 0.96 | N9: 12090.4 | O9: 9864.34
A10: 2 | B10: MT9 | C10: 319 Miền Trung | D10: UPCoM | I10: =$E10/F10-1 | J10: =$E10/G10-1 | K10: =$E10/H10-1
A11: 3 | B11: NBB | C11: 577 CORP | D11: HOSE | E11: 17150 | F11: 17300 | G11: 17200 | H11: 19500 | I11: =$E11/F11-1 | J11: =$E11/G11-1 | K11: =$E11/H11-1 | L11: 180.52 | M11: 0.95 | N11: 24950 | O11: 16100
A12: 4 | B12: AAV | C12: AAV Group | D12: UPCoM | E12: 6191 | F12: 6367 | G12: 6789 | H12: 6300 | I12: =$E12/F12-1 | J12: =$E12/G12-1 | K12: =$E12/H12-1 | L12: -19.77 | M12: 0.61 | N12: 9000 | O12: 5400
A13: 5 | B13: ACB | C13: ACB | D13: HOSE | E13: 22150 | F13: 22400 | G13: 22850 | H13: 20678.4 | I13: =$E13/F13-1 | J13: =$E13/G13-1 | K13: =$E13/H13-1 | L13: 8.2 | M13: 1.29 | N13: 25374.12 | O13: 18696.72 | P13: 6.93 | Q13: 1.42
A14: 6 | B14: AGR | C14: Agriseco | D14: HOSE | E14: 12850 | F14: 13050 | G14: 14650 | H14: 16100 | I14: =$E14/F14-1 | J14: =$E14/G14-1 | K14: =$E14/H14-1 | L14: 17.11 | M14: 1.11 | N14: 20550 | O14: 12250
A15: 7 | B15: AAA | C15: An Phát Bioplastics | D15: HOSE | E15: 7100 | F15: 7150 | G15: 6946.95 | H15: 7550.62 | I15: =$E15/F15-1 | J15: =$E15/G15-1 | K15: =$E15/H15-1 | L15: 5.11 | M15: 0.5 | N15: 8480.07 | O15: 6410.36
A16: 8 | B16: HII | C16: An Tiến Industries | D16: HOSE | E16: 8600 | F16: 8600 | G16: 5610 | H16: 5852.34 | I16: =$E16/F16-1 | J16: =$E16/G16-1 | K16: =$E16/H16-1 | L16: 2.7 | M16: 0.57 | N16: 9390 | O16: 4329.78
A17: 9 | B17: VNS | C17: Ánh Dương Việt Nam | D17: HOSE | E17: 7150 | F17: 7390 | G17: 7850 | H17: 9100 | I17: =$E17/F17-1 | J17: =$E17/G17-1 | K17: =$E17/H17-1 | L17: 431.92 | M17: 0.44 | N17: 9750 | O17: 7150
A18: 10 | B18: AMP | C18: Armephaco | D18: UPCoM | E18: 15000 | F18: 15500 | G18: 15071 | H18: 14700 | I18: =$E18/F18-1 | J18: =$E18/G18-1 | K18: =$E18/H18-1 | L18: 25.94 | M18: 0.93 | N18: 16500 | O18: 11000
A19: 11 | B19: ATG | C19: ATG Planet | D19: UPCoM | E19: 8100 | F19: 8100 | G19: 8600 | H19: 9500 | I19: =$E19/F19-1 | J19: =$E19/G19-1 | K19: =$E19/H19-1 | L19: 3.48 | M19: 13.93 | N19: 11500 | O19: 5574
A20: 12 | B20: TSB | C20: Ắc quy Tia Sáng | D20: HNX | E20: 21800 | F20: 21200 | G20: 21400 | H20: 27800 | I20: =$E20/F20-1 | J20: =$E20/G20-1 | K20: =$E20/H20-1 | L20: -106.34 | M20: 1.98 | N20: 39500 | O20: 18700
A21: 13 | B21: BCG | C21: Bamboo Capital | D21: UPCoM | E21: 2500 | F21: 2500 | G21: 2530 | H21: 2530 | I21: =$E21/F21-1 | J21: =$E21/G21-1 | K21: =$E21/H21-1 | L21: 4.7 | M21: 0.22 | N21: 3860 | O21: 2500
A22: 14 | B22: DBM | C22: BAMEPHARM | D22: UPCoM | E22: 25087 | F22: 31177 | G22: 24635.76 | H22: 23921.68 | I22: =$E22/F22-1 | J22: =$E22/G22-1 | K22: =$E22/H22-1 | L22: 10.49 | M22: 0.7 | N22: 31200 | O22: 18744.6
A23: 15 | B23: ECI | C23: Bản đồ và tranh ảnh GD | D23: HNX | E23: 9200 | F23: 9200 | G23: 9200 | H23: 9500 | I23: =$E23/F23-1 | J23: =$E23/G23-1 | K23: =$E23/H23-1 | L23: -33.98 | M23: 0.53 | N23: 15700 | O23: 7200
A24: 16 | B24: FRT | C24: Bán lẻ FPT | D24: HOSE | E24: 142900 | F24: 132000 | G24: 113600 | H24: 142383.8 | I24: =$E24/F24-1 | J24: =$E24/G24-1 | K24: =$E24/H24-1 | L24: 22.47 | M24: 5.32 | N24: 167146.2 | O24: 105000 | P24: 23.165 | Q24: 6.895
A25: 17 | B25: HCO | C25: Bánh kẹo Hải Châu | D25: UPCoM | I25: =$E25/F25-1 | J25: =$E25/G25-1 | K25: =$E25/H25-1
A26: 18 | B26: HHC | C26: Bánh kẹo Hải Hà | D26: HNX | E26: 95000 | F26: 74700 | G26: 76000 | H26: 149700 | I26: =$E26/F26-1 | J26: =$E26/G26-1 | K26: =$E26/H26-1 | L26: 28.62 | M26: 2.29 | N26: 167000 | O26: 67700
A27: 19 | B27: HNF | C27: Bánh kẹo Hữu Nghị | D27: UPCoM | E27: 22900 | F27: 23400 | G27: 21387 | H27: 32017.52 | I27: =$E27/F27-1 | J27: =$E27/G27-1 | K27: =$E27/H27-1 | L27: 6.78 | M27: 1.03 | N27: 34272.28 | O27: 20500
A28: 20 | B28: SGC | C28: Bánh phồng tôm Sa Giang | D28: HNX | E28: 104500 | F28: 104100 | G28: 106100 | H28: 82000 | I28: =$E28/F28-1 | J28: =$E28/G28-1 | K28: =$E28/H28-1 | L28: 5.68 | M28: 1.42 | N28: 113800 | O28: 75400
A29: 21 | B29: BAL | C29: Bao bì Balpac | D29: UPCoM | E29: 8500 | F29: 7500 | G29: 7100 | H29: 9500 | I29: =$E29/F29-1 | J29: =$E29/G29-1 | K29: =$E29/H29-1 | L29: 10.96 | M29: 0.56 | N29: 10426.9 | O29: 6200
A30: 22 | B30: BPC | C30: Bao bì Bỉm Sơn | D30: HNX | E30: 12500 | F30: 12500 | G30: 12500 | H30: 12300 | I30: =$E30/F30-1 | J30: =$E30/G30-1 | K30: =$E30/H30-1 | L30: 22.69 | M30: 0.51 | N30: 14583.92 | O30: 11000
A31: 23 | B31: PBP | C31: Bao bì Dầu khí VN | D31: HNX | E31: 11100 | F31: 11400 | G31: 12200 | H31: 12600 | I31: =$E31/F31-1 | J31: =$E31/G31-1 | K31: =$E31/H31-1 | L31: 6.68 | M31: 0.73 | N31: 13500 | O31: 11100
A32: 24 | B32: PMP | C32: Bao bì Đạm Phú Mỹ | D32: HNX | E32: 12000 | F32: 12000 | G32: 12000 | H32: 12500 | I32: =$E32/F32-1 | J32: =$E32/G32-1 | K32: =$E32/H32-1 | L32: 5.53 | M32: 0.66 | N32: 14932.8 | O32: 11500
A33: 25 | B33: BBH | C33: Bao bì Hoàng Thạch | D33: UPCoM | E33: 9500 | F33: 9000 | G33: 7600 | H33: 13412.22 | I33: =$E33/F33-1 | J33: =$E33/G33-1 | K33: =$E33/H33-1 | L33: 26.79 | M33: 0.26 | N33: 16522.3 | O33: 6839
A34: 26 | B34: HPB | C34: Bao bì PP | D34: UPCoM | E34: 18000 | F34: 18500 | G34: 18090 | H34: 14733.56 | I34: =$E34/F34-1 | J34: =$E34/G34-1 | K34: =$E34/H34-1 | L34: 7.99 | M34: 0.5 | N34: 37744.56 | O34: 11833.87
A35: 27 | B35: HBD | C35: Bao bì PP Bình Dương | D35: UPCoM | E35: 26000 | F35: 26000 | G35: 25800 | H35: 17751.7 | I35: =$E35/F35-1 | J35: =$E35/G35-1 | K35: =$E35/H35-1 | L35: 12.45 | M35: 1.35 | N35: 26400 | O35: 15415.95
A36: 28 | B36: TKA | C36: Bao bì Tân Khánh An | D36: UPCoM | E36: 3000 | F36: 3000 | G36: 3000 | H36: 3000 | I36: =$E36/F36-1 | J36: =$E36/G36-1 | K36: =$E36/H36-1 | L36: 1.09 | M36: 0.2 | N36: 3000 | O36: 2965.46
A37: 29 | B37: BTG | C37: Bao bì Tiền Giang | D37: UPCoM | E37: 8100 | F37: 8100 | G37: 8100 | H37: 7600 | I37: =$E37/F37-1 | J37: =$E37/G37-1 | K37: =$E37/H37-1 | L37: -5.86 | M37: 0.62 | N37: 10300 | O37: 7600
... A62: 54 | B62: LEC | C62: BĐS Điện lực Miền Trung | D62: UPCoM | E62: 4500 | F62: 4500 | G62: 4500 | H62: 3300 | I62: =$E62/F62-1 | J62: =$E62/G62-1 | K62: =$E62/H62-1 | L62: -5.62 | M62: 0.52 | N62: 5806 | O62: 3100
A63: 55 | B63: NLG | C63: BĐS Nam Long | D63: HOSE | E63: 22800 | F63: 22200 | G63: 25300 | H63: 29874.5 | I63: =$E63/F63-1 | J63: =$E63/G63-1 | K63: =$E63/H63-1 | L63: 16.2 | M63: 0.88 | N63: 40633.98 | O63: 20000 | P63: 21.32 | Q63: 1.58
A64: 56 | B64: PDR | C64: BĐS Phát Đạt | D64: HOSE | E64: 11950 | F64: 11900 | G64: 13900 | H64: 18800 | I64: =$E64/F64-1 | J64: =$E64/G64-1 | K64: =$E64/H64-1 | L64: 19.3 | M64: 0.95 | N64: 26300 | O64: 11150 | P64: 27.77 | Q64: 1.78
A65: 57 | B65: LSG | C65: BĐS Sài Gòn Vina | D65: UPCoM | E65: 34323 | F65: 35075 | G65: 34589 | H65: 32297 | I65: =$E65/F65-1 | J65: =$E65/G65-1 | K65: =$E65/H65-1 | L65: 45.35 | M65: 2.8 | N65: 38833 | O65: 20208
A66: 58 | B66: PPI | C66: BĐS Thái Bình Dương | D66: UPCoM | E66: 400 | F66: 400 | G66: 400 | H66: 400 | I66: =$E66/F66-1 | J66: =$E66/G66-1 | K66: =$E66/H66-1 | L66: -5.72 | M66: -0.13 | N66: 400 | O66: 400
A67: 59 | B67: BCM | C67: Becamex Group | D67: HOSE | E67: 43050 | F67: 38600 | G67: 47050 | H67: 60749.4 | I67: =$E67/F67-1 | J67: =$E67/G67-1 | K67: =$E67/H67-1 | L67: 20.83 | M67: 2.04 | N67: 78640 | O67: 35000 | P67: 28.87 | Q67: 3.735
A68: 60 | B68: IJC | C68: Becamex IJC | D68: HOSE | E68: 7430 | F68: 7420 | G68: 8150 | H68: 10186.7 | I68: =$E68/F68-1 | J68: =$E68/G68-1 | K68: =$E68/H68-1 | L68: 6.23 | M68: 0.59 | N68: 13455.92 | O68: 6690 | P68: 9.225 | Q68: 1.02
A69: 61 | B69: TDC | C69: Becamex TDC | D69: HOSE | E69: 7480 | F69: 7250 | G69: 7790 | H69: 10887.86 | I69: =$E69/F69-1 | J69: =$E69/G69-1 | K69: =$E69/H69-1 | L69: 4.34 | M69: 0.55 | N69: 13379.15 | O69: 6870
...
